Workbook

Sheet はじめに
A1: 嫁子のスカッと朗読劇場【スカッとする話】 転載対策シート
A2: 作成日 | B2: 2026-09-16
A4: シート | B4: 内容
A5: ラウンド0_検索上位の転載 | B5: 本家より検索上位に表示されている転載164本。最優先で削除申請する。
A6: ラウンド1 | B6: 上位100チャンネルに1本ずつ＋101位以降はまとめて。警告1回目。
A7: ラウンド2 | B7: ラウンド1の削除実行後、上位100チャンネルにもう1本ずつ。
A8: ラウンド3 | B8: ラウンド2の実行後にもう1本ずつ。ここで相手チャンネル停止。
A9: チャンネル別集計 | B9: 819チャンネルの転載本数。全転載一覧の申請日・削除確認を埋めると自動で集計される。
A10: 全転載一覧 | B10: 現存する転載2,412本の全件。
A11: 本家が圏外 | B11: 本家が検索100位以内に出なかった元動画12本。転載以外の原因を確認。
A13: 黄色のセル | B13: 申請日・削除確認・メモを記入する欄。
A14: 一致率 | B14: タイトルの文字一致率。100%はタイトルが一言一句同じ。
A15: 注意 | B15: 申請前に転載動画を10秒再生し、ナレーションが嫁子の音声であることを確認する。虚偽申請は自チャンネルの停止リスク。
... A17: 記入例 | B17: 申請日「9/17」、削除確認「9/20」のように日付を入れる。

Sheet チャンネル別集計
A1: 順位 | B1: チャンネル名 | C1: チャンネルURL | D1: 転載本数 | E1: 直近の投稿 | F1: 主な形式 | G1: 申請済み本数 | H1: 削除済み本数 | I1: メモ
A2: 1 | B2: 藤田 七海 | C2: https://www.youtube.com/channel/UCe0KTxGVR84qUjkAHQb-wGg | D2: =COUNTIF(全転載一覧!$B$2:$B$2413,B2) | E2: 2 週間前 | F2: 朗読/同形式 | G2: =COUNTIFS(全転載一覧!$B$2:$B$2413,B2,全転載一覧!$N$2:$N$2413,"<>") | H2: =COUNTIFS(全転載一覧!$B$2:$B$2413,B2,全転載一覧!$O$2:$O$2413,"<>")
A3: 2 | B3: スカッと物語 | C3: https://www.youtube.com/channel/UCLz5UoQMIAja9LyZIOCYmQg | D3: =COUNTIF(全転載一覧!$B$2:$B$2413,B3) | E3: 8 日前 | F3: 朗読/同形式 | G3: =COUNTIFS(全転載一覧!$B$2:$B$2413,B3,全転載一覧!$N$2:$N$2413,"<>") | H3: =COUNTIFS(全転載一覧!$B$2:$B$2413,B3,全転載一覧!$O$2:$O$2413,"<>")
A4: 3 | B4: 出る杭は打たれる | C4: https://www.youtube.com/channel/UCAmIDIbiOxKA9YSVK0aYSZQ | D4: =COUNTIF(全転載一覧!$B$2:$B$2413,B4) | E4: 2 か月前 | F4: 朗読/同形式 | G4: =COUNTIFS(全転載一覧!$B$2:$B$2413,B4,全転載一覧!$N$2:$N$2413,"<>") | H4: =COUNTIFS(全転載一覧!$B$2:$B$2413,B4,全転載一覧!$O$2:$O$2413,"<>")
A5: 4 | B5: 良い話 | C5: https://www.youtube.com/channel/UCSrk1OzKlw4sCvRbksLDgcQ | D5: =COUNTIF(全転載一覧!$B$2:$B$2413,B5) | E5: 5 日前 | F5: 朗読/同形式 | G5: =COUNTIFS(全転載一覧!$B$2:$B$2413,B5,全転載一覧!$N$2:$N$2413,"<>") | H5: =COUNTIFS(全転載一覧!$B$2:$B$2413,B5,全転載一覧!$O$2:$O$2413,"<>")
A6: 5 | B6: 家庭の真実 5497 | C6: https://www.youtube.com/channel/UCqzVZHS7_AHD3WczZdnOkwg | D6: =COUNTIF(全転載一覧!$B$2:$B$2413,B6) | E6: 3 週間前 | F6: 朗読/同形式 | G6: =COUNTIFS(全転載一覧!$B$2:$B$2413,B6,全転載一覧!$N$2:$N$2413,"<>") | H6: =COUNTIFS(全転載一覧!$B$2:$B$2413,B6,全転載一覧!$O$2:$O$2413,"<>")
A7: 6 | B7: スカッとストーリー 5006 | C7: https://www.youtube.com/channel/UC1x3I0LM2SzXkpn57uaFuQA | D7: =COUNTIF(全転載一覧!$B$2:$B$2413,B7) | E7: 1 か月前 | F7: 朗読/同形式 | G7: =COUNTIFS(全転載一覧!$B$2:$B$2413,B7,全転載一覧!$N$2:$N$2413,"<>") | H7: =COUNTIFS(全転載一覧!$B$2:$B$2413,B7,全転載一覧!$O$2:$O$2413,"<>")
A8: 7 | B8: 嫁ゴコロ逆転朗読館 | C8: https://www.youtube.com/channel/UCQDSjWHn0tvkuVZav4jZnXQ | D8: =COUNTIF(全転載一覧!$B$2:$B$2413,B8) | E8: 6 日前 | F8: 朗読/同形式 | G8: =COUNTIFS(全転載一覧!$B$2:$B$2413,B8,全転載一覧!$N$2:$N$2413,"<>") | H8: =COUNTIFS(全転載一覧!$B$2:$B$2413,B8,全転載一覧!$O$2:$O$2413,"<>")
A9: 8 | B9: 読書室【スカッとする話】 | C9: https://www.youtube.com/channel/UCjQd7ZVm5BPbGpB_V9B6kgQ | D9: =COUNTIF(全転載一覧!$B$2:$B$2413,B9) | E9: 1 年前 | F9: 朗読/同形式 | G9: =COUNTIFS(全転載一覧!$B$2:$B$2413,B9,全転載一覧!$N$2:$N$2413,"<>") | H9: =COUNTIFS(全転載一覧!$B$2:$B$2413,B9,全転載一覧!$O$2:$O$2413,"<>")
A10: 9 | B10: 憂鬱よりスカッと | C10: https://www.youtube.com/channel/UC8bvniIkSPPf_5ELr1VNZCQ | D10: =COUNTIF(全転載一覧!$B$2:$B$2413,B10) | E10: 2 年前 | F10: 朗読/同形式 | G10: =COUNTIFS(全転載一覧!$B$2:$B$2413,B10,全転載一覧!$N$2:$N$2413,"<>") | H10: =COUNTIFS(全転載一覧!$B$2:$B$2413,B10,全転載一覧!$O$2:$O$2413,"<>")
A11: 10 | B11: とする話 | C11: https://www.youtube.com/channel/UC-1KoQRWd1ijwgKpAmRTQ7A | D11: =COUNTIF(全転載一覧!$B$2:$B$2413,B11) | E11: 1 年前 | F11: 朗読/同形式 | G11: =COUNTIFS(全転載一覧!$B$2:$B$2413,B11,全転載一覧!$N$2:$N$2413,"<>") | H11: =COUNTIFS(全転載一覧!$B$2:$B$2413,B11,全転載一覧!$O$2:$O$2413,"<>")
A12: 11 | B12: Dima Tomashevich | C12: https://www.youtube.com/channel/UCkfiH3lPVPodePE4eNSDpWg | D12: =COUNTIF(全転載一覧!$B$2:$B$2413,B12) | E12: 2 年前 | F12: 朗読/同形式 | G12: =COUNTIFS(全転載一覧!$B$2:$B$2413,B12,全転載一覧!$N$2:$N$2413,"<>") | H12: =COUNTIFS(全転載一覧!$B$2:$B$2413,B12,全転載一覧!$O$2:$O$2413,"<>")
A13: 12 | B13: さあ、どうぞ | C13: https://www.youtube.com/channel/UCG-XF2tttCtNESz__p6GQ7w | D13: =COUNTIF(全転載一覧!$B$2:$B$2413,B13) | E13: 2 か月前 | F13: 朗読/同形式 | G13: =COUNTIFS(全転載一覧!$B$2:$B$2413,B13,全転載一覧!$N$2:$N$2413,"<>") | H13: =COUNTIFS(全転載一覧!$B$2:$B$2413,B13,全転載一覧!$O$2:$O$2413,"<>")
... A18: 17 | B18: 義家族スカッと物語帳 | C18: https://www.youtube.com/channel/UCIZ41RBpQd7wBp_oOTGv1zw | D18: =COUNTIF(全転載一覧!$B$2:$B$2413,B18) | E18: 6 日前 | F18: 朗読/同形式 | G18: =COUNTIFS(全転載一覧!$B$2:$B$2413,B18,全転載一覧!$N$2:$N$2413,"<>") | H18: =COUNTIFS(全転載一覧!$B$2:$B$2413,B18,全転載一覧!$O$2:$O$2413,"<>")
A19: 18 | B19: 静かな夜の物語、雨の中の記憶 | D19: =COUNTIF(全転載一覧!$B$2:$B$2413,B19) | E19: 2 週間前 | F19: 朗読/同形式 | G19: =COUNTIFS(全転載一覧!$B$2:$B$2413,B19,全転載一覧!$N$2:$N$2413,"<>") | H19: =COUNTIFS(全転載一覧!$B$2:$B$2413,B19,全転載一覧!$O$2:$O$2413,"<>")
A20: 19 | B20: Noah Qumi | C20: https://www.youtube.com/channel/UCH4l3-r5NgR2RlKdoRwfzAw | D20: =COUNTIF(全転載一覧!$B$2:$B$2413,B20) | E20: 7 日前 | F20: 朗読/同形式 | G20: =COUNTIFS(全転載一覧!$B$2:$B$2413,B20,全転載一覧!$N$2:$N$2413,"<>") | H20: =COUNTIFS(全転載一覧!$B$2:$B$2413,B20,全転載一覧!$O$2:$O$2413,"<>")
A21: 20 | B21: Shinji Datの人生物語 | C21: https://www.youtube.com/channel/UCpdX_bFCePsYvPWZAMQoaeg | D21: =COUNTIF(全転載一覧!$B$2:$B$2413,B21) | E21: 2 か月前 | F21: 朗読/同形式 | G21: =COUNTIFS(全転載一覧!$B$2:$B$2413,B21,全転載一覧!$N$2:$N$2413,"<>") | H21: =COUNTIFS(全転載一覧!$B$2:$B$2413,B21,全転載一覧!$O$2:$O$2413,"<>")
A22: 21 | B22: スカッとする話 5020 | C22: https://www.youtube.com/channel/UCAG5eZR0aJpGuShtjtimSEg | D22: =COUNTIF(全転載一覧!$B$2:$B$2413,B22) | E22: 4 週間前 | F22: 朗読/同形式 | G22: =COUNTIFS(全転載一覧!$B$2:$B$2413,B22,全転載一覧!$N$2:$N$2413,"<>") | H22: =COUNTIFS(全転載一覧!$B$2:$B$2413,B22,全転載一覧!$O$2:$O$2413,"<>")
A23: 22 | B23: 人生の光と影 | C23: https://www.youtube.com/channel/UCYX4tsWpykTmtfNq_i36C_w | D23: =COUNTIF(全転載一覧!$B$2:$B$2413,B23) | E23: 8 日前 | F23: 朗読/同形式 | G23: =COUNTIFS(全転載一覧!$B$2:$B$2413,B23,全転載一覧!$N$2:$N$2413,"<>") | H23: =COUNTIFS(全転載一覧!$B$2:$B$2413,B23,全転載一覧!$O$2:$O$2413,"<>")
A24: 23 | B24: 美しい木 | C24: https://www.youtube.com/channel/UCKDhvWl0boDNeo65NQzjbOg | D24: =COUNTIF(全転載一覧!$B$2:$B$2413,B24) | E24: 3 か月前 | F24: 朗読/同形式 | G24: =COUNTIFS(全転載一覧!$B$2:$B$2413,B24,全転載一覧!$N$2:$N$2413,"<>") | H24: =COUNTIFS(全転載一覧!$B$2:$B$2413,B24,全転載一覧!$O$2:$O$2413,"<>")
A25: 24 | B25: TINA SHTIBKO | C25: https://www.youtube.com/channel/UCIQbb4FNm2BhP5GfSTbrQ4w | D25: =COUNTIF(全転載一覧!$B$2:$B$2413,B25) | E25: 2 年前 | F25: 朗読/同形式 | G25: =COUNTIFS(全転載一覧!$B$2:$B$2413,B25,全転載一覧!$N$2:$N$2413,"<>") | H25: =COUNTIFS(全転載一覧!$B$2:$B$2413,B25,全転載一覧!$O$2:$O$2413,"<>")
A26: 25 | B26: フィクション 5634 | C26: https://www.youtube.com/channel/UCtx1aitp-eTJhv2c94bnBZQ | D26: =COUNTIF(全転載一覧!$B$2:$B$2413,B26) | E26: 3 週間前 | F26: 朗読/同形式 | G26: =COUNTIFS(全転載一覧!$B$2:$B$2413,B26,全転載一覧!$N$2:$N$2413,"<>") | H26: =COUNTIFS(全転載一覧!$B$2:$B$2413,B26,全転載一覧!$O$2:$O$2413,"<>")
A27: 26 | B27: 泥だらけの絆 5655 | C27: https://www.youtube.com/channel/UCdyvc7k9wPzVO9X62aCvguQ | D27: =COUNTIF(全転載一覧!$B$2:$B$2413,B27) | E27: 13 日前 | F27: 朗読/同形式 | G27: =COUNTIFS(全転載一覧!$B$2:$B$2413,B27,全転載一覧!$N$2:$N$2413,"<>") | H27: =COUNTIFS(全転載一覧!$B$2:$B$2413,B27,全転載一覧!$O$2:$O$2413,"<>")
A28: 27 | B28: Bonnie Denver | C28: https://www.youtube.com/channel/UCsdndA886timZqWK6_b0d0Q | D28: =COUNTIF(全転載一覧!$B$2:$B$2413,B28) | E28: 1 年前 | F28: 朗読/同形式 | G28: =COUNTIFS(全転載一覧!$B$2:$B$2413,B28,全転載一覧!$N$2:$N$2413,"<>") | H28: =COUNTIFS(全転載一覧!$B$2:$B$2413,B28,全転載一覧!$O$2:$O$2413,"<>")
A29: 28 | B29: 心温まるストーリー 4989 | C29: https://www.youtube.com/channel/UCS-VuYFB_DXsDhPHAzUS0JA | D29: =COUNTIF(全転載一覧!$B$2:$B$2413,B29) | E29: 1 か月前 | F29: 朗読/同形式 | G29: =COUNTIFS(全転載一覧!$B$2:$B$2413,B29,全転載一覧!$N$2:$N$2413,"<>") | H29: =COUNTIFS(全転載一覧!$B$2:$B$2413,B29,全転載一覧!$O$2:$O$2413,"<>")
A30: 29 | B30: Jamison Abraham | C30: https://www.youtube.com/channel/UCcUsK23eqHw3ZQA5HjspM9Q | D30: =COUNTIF(全転載一覧!$B$2:$B$2413,B30) | E30: 1 年前 | F30: 朗読/同形式 | G30: =COUNTIFS(全転載一覧!$B$2:$B$2413,B30,全転載一覧!$N$2:$N$2413,"<>") | H30: =COUNTIFS(全転載一覧!$B$2:$B$2413,B30,全転載一覧!$O$2:$O$2413,"<>")
A31: 30 | B31: サヨナラの選択4848 | C31: https://www.youtube.com/channel/UCiDg2Vs1LHy6qIiV6ilje1A | D31: =COUNTIF(全転載一覧!$B$2:$B$2413,B31) | E31: 3 週間前 | F31: 朗読/同形式 | G31: =COUNTIFS(全転載一覧!$B$2:$B$2413,B31,全転載一覧!$N$2:$N$2413,"<>") | H31: =COUNTIFS(全転載一覧!$B$2:$B$2413,B31,全転載一覧!$O$2:$O$2413,"<>")
... A38: 37 | B38: 痛快!!怒りのスカッとチャンネル【スカッと朗読】 | C38: https://www.youtube.com/channel/UC96mO8pXAaiP70V7KUjVHqg | D38: =COUNTIF(全転載一覧!$B$2:$B$2413,B38) | E38: 1 年前 | F38: 朗読/同形式 | G38: =COUNTIFS(全転載一覧!$B$2:$B$2413,B38,全転載一覧!$N$2:$N$2413,"<>") | H38: =COUNTIFS(全転載一覧!$B$2:$B$2413,B38,全転載一覧!$O$2:$O$2413,"<>")
A39: 38 | B39: 雨の中の記憶、雨の中の記憶 | D39: =COUNTIF(全転載一覧!$B$2:$B$2413,B39) | E39: 3 週間前 | F39: 朗読/同形式 | G39: =COUNTIFS(全転載一覧!$B$2:$B$2413,B39,全転載一覧!$N$2:$N$2413,"<>") | H39: =COUNTIFS(全転載一覧!$B$2:$B$2413,B39,全転載一覧!$O$2:$O$2413,"<>")
A40: 39 | B40: スカっとゼミ!! | C40: https://www.youtube.com/channel/UC9Hd679L2faWD0aJQHeAlrA | D40: =COUNTIF(全転載一覧!$B$2:$B$2413,B40) | E40: 1 年前 | F40: 朗読/同形式 | G40: =COUNTIFS(全転載一覧!$B$2:$B$2413,B40,全転載一覧!$N$2:$N$2413,"<>") | H40: =COUNTIFS(全転載一覧!$B$2:$B$2413,B40,全転載一覧!$O$2:$O$2413,"<>")
A41: 40 | B41: スカッと成敗ストーリー | C41: https://www.youtube.com/channel/UC1iIGo491nSYyJ_AsgmPzyw | D41: =COUNTIF(全転載一覧!$B$2:$B$2413,B41) | E41: 2 か月前 | F41: 朗読/同形式 | G41: =COUNTIFS(全転載一覧!$B$2:$B$2413,B41,全転載一覧!$N$2:$N$2413,"<>") | H41: =COUNTIFS(全転載一覧!$B$2:$B$2413,B41,全転載一覧!$O$2:$O$2413,"<>")
A42: 41 | B42: 時を越える話 | C42: https://www.youtube.com/channel/UC_n9gc1na-2QpFv6TPInL3w | D42: =COUNTIF(全転載一覧!$B$2:$B$2413,B42) | E42: 3 週間前 | F42: 朗読/同形式 | G42: =COUNTIFS(全転載一覧!$B$2:$B$2413,B42,全転載一覧!$N$2:$N$2413,"<>") | H42: =COUNTIFS(全転載一覧!$B$2:$B$2413,B42,全転載一覧!$O$2:$O$2413,"<>")
A43: 42 | B43: 涙の向こう側 | C43: https://www.youtube.com/channel/UCOXAYjsxUMpublA1yS1ATIA | D43: =COUNTIF(全転載一覧!$B$2:$B$2413,B43) | E43: 8 日前 | F43: 朗読/同形式 | G43: =COUNTIFS(全転載一覧!$B$2:$B$2413,B43,全転載一覧!$N$2:$N$2413,"<>") | H43: =COUNTIFS(全転載一覧!$B$2:$B$2413,B43,全転載一覧!$O$2:$O$2413,"<>")
A44: 43 | B44: 老いの詩 | C44: https://www.youtube.com/channel/UClKj-HO63gh7qxtT7M0czEQ | D44: =COUNTIF(全転載一覧!$B$2:$B$2413,B44) | E44: 1 か月前 | F44: 朗読/同形式 | G44: =COUNTIFS(全転載一覧!$B$2:$B$2413,B44,全転載一覧!$N$2:$N$2413,"<>") | H44: =COUNTIFS(全転載一覧!$B$2:$B$2413,B44,全転載一覧!$O$2:$O$2413,"<>")
A45: 44 | B45: Ivan Ilencow | C45: https://www.youtube.com/channel/UC6IzQHpKzqIt1DgjPouEefQ | D45: =COUNTIF(全転載一覧!$B$2:$B$2413,B45) | E45: 2 年前 | F45: 朗読/同形式 | G45: =COUNTIFS(全転載一覧!$B$2:$B$2413,B45,全転載一覧!$N$2:$N$2413,"<>") | H45: =COUNTIFS(全転載一覧!$B$2:$B$2413,B45,全転載一覧!$O$2:$O$2413,"<>")
A46: 45 | B46: Legacy Apollo | C46: https://www.youtube.com/channel/UC2YwIXq-utTkNLQgcRVloyQ | D46: =COUNTIF(全転載一覧!$B$2:$B$2413,B46) | E46: 2 年前 | F46: 朗読/同形式 | G46: =COUNTIFS(全転載一覧!$B$2:$B$2413,B46,全転載一覧!$N$2:$N$2413,"<>") | H46: =COUNTIFS(全転載一覧!$B$2:$B$2413,B46,全転載一覧!$O$2:$O$2413,"<>")
A47: 46 | B47: Pendelton Gideon | C47: https://www.youtube.com/channel/UCIRVjzjmTHwXA3X81dpyNeQ | D47: =COUNTIF(全転載一覧!$B$2:$B$2413,B47) | E47: 1 年前 | F47: 朗読/同形式 | G47: =COUNTIFS(全転載一覧!$B$2:$B$2413,B47,全転載一覧!$N$2:$N$2413,"<>") | H47: =COUNTIFS(全転載一覧!$B$2:$B$2413,B47,全転載一覧!$O$2:$O$2413,"<>")
A48: 47 | B48: Павел **** | C48: https://www.youtube.com/channel/UCSPg9ALk7YwnsqACClpErGg | D48: =COUNTIF(全転載一覧!$B$2:$B$2413,B48) | E48: 2 年前 | F48: 朗読/同形式 | G48: =COUNTIFS(全転載一覧!$B$2:$B$2413,B48,全転載一覧!$N$2:$N$2413,"<>") | H48: =COUNTIFS(全転載一覧!$B$2:$B$2413,B48,全転載一覧!$O$2:$O$2413,"<>")
A49: 48 | B49: 人生スカッと朗読館 | C49: https://www.youtube.com/channel/UChTkZ7g3oCCQG3XSqe69LWQ | D49: =COUNTIF(全転載一覧!$B$2:$B$2413,B49) | E49: 5 日前 | F49: 朗読/同形式 | G49: =COUNTIFS(全転載一覧!$B$2:$B$2413,B49,全転載一覧!$N$2:$N$2413,"<>") | H49: =COUNTIFS(全転載一覧!$B$2:$B$2413,B49,全転載一覧!$O$2:$O$2413,"<>")
A50: 49 | B50: 夜の語り部5056 | C50: https://www.youtube.com/channel/UCEvaB4r-6y7tj3UAoMEdqXA | D50: =COUNTIF(全転載一覧!$B$2:$B$2413,B50) | E50: 1 か月前 | F50: 朗読/同形式 | G50: =COUNTIFS(全転載一覧!$B$2:$B$2413,B50,全転載一覧!$N$2:$N$2413,"<>") | H50: =COUNTIFS(全転載一覧!$B$2:$B$2413,B50,全転載一覧!$O$2:$O$2413,"<>")
...

Sheet ラウンド0_検索上位の転載
A1: No. | B1: 申請日 | C1: 削除確認 | D1: チャンネル名 | E1: チャンネルURL | F1: 転載動画URL | G1: 転載の検索順位 | H1: 本家の検索順位 | I1: 転載の投稿 | J1: 転載の再生数 | K1: 元動画URL | L1: 元動画の再生数 | M1: 元タイトル | N1: メモ
A2: 1 | D2: 実話感動チャンネル | E2: https://www.youtube.com/channel/UCekQO8WQ0udVSYSfX4Pymgw | F2: https://www.youtube.com/watch?v=jv_tPg2W6KU | G2: 1 | H2: 2 | I2: 2 か月前 | J2: 27912 | K2: https://www.youtube.com/watch?v=p4pyD9SD1Tk | L2: 81000 | M2: 【スカッとする話】義両親に蹴られ骨折した私に夫「寝かせとけば治るw」翌日、病室に嘲笑いに来た義家族「あれ、嫁は？w」医師「警察署です」義家族「え？」【朗読】【スカッと】
A3: 2 | D3: 実話感動チャンネル | E3: https://www.youtube.com/channel/UCekQO8WQ0udVSYSfX4Pymgw | F3: https://www.youtube.com/watch?v=qFlVMlu5W_s | G3: 1 | H3: 2 | I3: 3 か月前 | J3: 13613 | K3: https://www.youtube.com/watch?v=nlS5u4pCtI0 | L3: 38000 | M3: 【スカッとする話】警察官の弟の結婚式に出席した私。義母「中卒の姉は一族の恥ねw」直後、慌てた弟が義母に私の正体を伝えると、義母は顔面蒼白に…【朗読】【スカッと】
A4: 3 | D4: 実話感動チャンネル | E4: https://www.youtube.com/channel/UCekQO8WQ0udVSYSfX4Pymgw | F4: https://www.youtube.com/watch?v=3Y0kz4vBXE4 | G4: 1 | H4: 2 | I4: 3 か月前 | J4: 11882 | K4: https://www.youtube.com/watch?v=Tpbu9uHiFPg | L4: 110000 | M4: 【スカッとする話】結婚10年目に銀行員の夫が突然の暴露「お前の親友と結婚するw籍入れてないし財産分与は無しw」私「あれ？あんた知らないの？」夫「何がだよw」実は…
A5: 4 | D5: 実話感動チャンネル | E5: https://www.youtube.com/channel/UCekQO8WQ0udVSYSfX4Pymgw | F5: https://www.youtube.com/watch?v=wC808VvKID0 | G5: 1 | H5: 2 | I5: 2 か月前 | J5: 5598 | K5: https://www.youtube.com/watch?v=9kcEIi88egw | L5: 230000 | M5: 【スカッとする話】自ら命を絶った夫が亡くなり1週間後、私宛に夫から手紙が届いた...手紙「両親に見つからず読んでくれ」そこに記された場所に行き同封の鍵でコインロッカーを開けると...
A6: 5 | D6: 家族の修羅場 | E6: https://www.youtube.com/channel/UCBh3ipHGoPZMTeNkEWdf5kQ | F6: https://www.youtube.com/watch?v=TgQ5XyInIK4 | G6: 1 | H6: 2 | I6: 7 か月前 | J6: 3 | K6: https://www.youtube.com/watch?v=RAvd6Tel5z0 | L6: 27000 | M6: 【スカッとする話】初孫の初節句のお祝いで料亭に行くと私だけ料理がない…長男嫁「家族の分しかないですよw」私「じゃあ他人は帰りますね。仕送り30万もやめるから」
A7: 6 | D7: 家族の修羅場 | E7: https://www.youtube.com/channel/UCBh3ipHGoPZMTeNkEWdf5kQ | F7: https://www.youtube.com/watch?v=73K4XYt9xrc | G7: 1 | H7: 2 | I7: 7 か月前 | J7: 0 | K7: https://www.youtube.com/watch?v=XKULaOclsHw | L7: 19000 | M7: 【スカッとする話】母が危篤になり病院へ急ぐ私に夫「他人のババァとか興味ないwてか出張中は連絡するなw」2週間後、満面の笑みで夫が帰ると→私「お義母さんの葬儀、終わったよ」
A8: 7 | D8: 家族の修羅場 | E8: https://www.youtube.com/channel/UCBh3ipHGoPZMTeNkEWdf5kQ | F8: https://www.youtube.com/watch?v=Dw56BW6dv8A | G8: 1 | H8: 2 | I8: 7 か月前 | J8: 0 | K8: https://www.youtube.com/watch?v=Hf2l_WByhX8 | L8: 15000 | M8: 【スカッとする話】私「ボーナスとミニバンが消えた！」夫「還暦祝いで母さんに譲ったw文句あるなら離婚するぞw」3日後、半狂乱の義母から鬼電→私「あんた誰？」【スカッと】【朗読】
A9: 8 | D9: 家族の修羅場 | E9: https://www.youtube.com/channel/UCBh3ipHGoPZMTeNkEWdf5kQ | F9: https://www.youtube.com/watch?v=hU_nHDJY2IQ | G9: 1 | H9: 2 | I9: 7 か月前 | J9: 0 | K9: https://www.youtube.com/watch?v=AkFPFwnz6fs | L9: 55000 | M9: 【スカッとする話】1億の一軒家に住む金持ち自慢の婚約者の実家へ結婚挨拶に行くと、義父「なんだ？不細工な嫁だなw」義母「親の顔が見てみたいわねw」→母「どうも、不細工の母です」義両親「え？あなたは…」
A10: 9 | D10: Văn Sơn Lã | E10: https://www.youtube.com/channel/UCnSrambnfB2Nc_4BliQ4Aug | F10: https://www.youtube.com/watch?v=hDurNSA0XVU | G10: 1 | H10: 2 | I10: 1 年前 | J10: 0 | K10: https://www.youtube.com/watch?v=a207sJNOihM | L10: 87000 | M10: 【スカッとする話】浮気中の夫が意識不明で運ばれ、救急隊員「意識不明の重体です！」私「旦那じゃありません」無視して夫の人生終了させた結果w
A11: 10 | D11: Văn Sơn Lã | E11: https://www.youtube.com/channel/UCnSrambnfB2Nc_4BliQ4Aug | F11: https://www.youtube.com/watch?v=x6IaaxpWj6s | G11: 1 | H11: 2 | I11: 1 年前 | J11: 0 | K11: https://www.youtube.com/watch?v=urrn4wk835o | L11: 100000 | M11: 【スカッとする話】事故で半身不随の夫の見舞いに来た8歳の姪「この手紙ばぁばから預かったの。夫さんに隠れて読んでって」手紙を確認した私は慌てて夫のズボンを脱がし...
A12: 11 | D12: Văn Sơn Lã | E12: https://www.youtube.com/channel/UCnSrambnfB2Nc_4BliQ4Aug | F12: https://www.youtube.com/watch?v=xOwGZi2Qd64 | G12: 1 | H12: 2 | I12: 1 年前 | J12: 1 | K12: https://www.youtube.com/watch?v=14YEbx6YYwk | L12: 42000 | M12: 【スカッとする話】家事に疲れて休憩していると妊娠9ヶ月の私を蹴ってきた夫「妊婦だからは甘え！家事サボるな！」無視した私に夫がビール瓶を投げるも当たって血まみれになったのは...
A13: 12 | D13: 人生スカッと朗読館 | E13: https://www.youtube.com/channel/UChTkZ7g3oCCQG3XSqe69LWQ | F13: https://www.youtube.com/watch?v=qsjIpApuEeQ | G13: 1 | H13: 2 | I13: 6 日前 | J13: 0 | K13: https://www.youtube.com/watch?v=hi2PAohyTkU | L13: 20000 | M13: 【スカッとする話】夫の出張中、オウムを任された私。何気なくオウムに話しかけると、オウム「嫁にはバレてないよ」不審に思い夫の部屋を開けた。→直後、私は顔面蒼白に…【朗読ドラマ】【朗読】【スカッと】
... A64: 63 | D64: 話題のLINE | E64: https://www.youtube.com/channel/UCPUjukg0U7MOqNIw_4l5hkA | F64: https://www.youtube.com/watch?v=ljV5pcl0_Uw | G64: 1 | H64: 3 | I64: 2 年前 | J64: 526913 | K64: https://www.youtube.com/watch?v=iT0GjRHrB6w | L64: 260000 | M64: 【スカッとする話】年末年始の親族の集まりで20人分のおせちをゴミ箱にぶちまけたエリート夫「親戚にマズイ飯を作るな！」私「私は何も作ってないよ？」夫「え？」実は...
A65: 64 | D65: 静かな夜の物語、雨の中の記憶 | F65: https://www.youtube.com/watch?v=ze9iOqJewBo | G65: 1 | H65: 2 | I65: 2 週間前 | J65: 0 | K65: https://www.youtube.com/watch?v=T40Q2m3NnVw | L65: 60000 | M65: 【スカッとする話】私の里帰り中に医者の婚約者を略奪した姉から連絡「彼の赤ちゃん妊娠したwアンタは帰ってくるなw」私「いいの？有り難う！」そのまま新居に引越した結果w
A66: 65 | D66: 静かな夜の物語、雨の中の記憶 | F66: https://www.youtube.com/watch?v=o0udygfbu2Y | G66: 1 | H66: 圏外 | I66: 10 日前 | J66: 2 | K66: https://www.youtube.com/watch?v=cF4ti4NhgGU | L66: 170000 | M66: 【スカッとする話】地下室に隠れ夫と親友が真っ最中だった...母「嫁子、戸締りしておいたわよ！」ど天然の母が気づかず鍵を閉めたので永遠に放置し新居に引越した結果w
A67: 66 | D67: 静かな夜の物語、静かな心の記録 | F67: https://www.youtube.com/watch?v=GzdH1HjwK5s | G67: 1 | H67: 2 | I67: 1 か月前 | J67: 0 | K67: https://www.youtube.com/watch?v=Eh0FIn_sub0 | L67: 56000 | M67: 【スカッとする話】8歳の姪「1日だけ泊めて下さい...」大雪の中、赤ちゃんを抱き抱えボロボロの姿で現れた姪...。夫「え？それは無理だよ？」姪「そんな…涙」→結果
A68: 67 | D68: 静かな夜の物語、静かな心の記録 | F68: https://www.youtube.com/watch?v=zcVtcsNhvSU | G68: 1 | H68: 2 | I68: 23 時間前 | J68: 0 | K68: https://www.youtube.com/watch?v=-EQHZjnhA9w | L68: 28000 | M68: 【スカッとする話】一人暮らしの私のことを気遣う娘に私「いつも仕送りありがとう。月1000円でも気持ちが嬉しいわよ」娘「え？毎月13万送金してるよ？」私「えっ？」直後、娘が私の銀行口座を止めると...
A69: 68 | D69: 読書室【スカッとする話】 | E69: https://www.youtube.com/channel/UCjQd7ZVm5BPbGpB_V9B6kgQ | F69: https://www.youtube.com/watch?v=ItiHHN9nAoE | G69: 2 | H69: 3 | I69: 1 年前 | J69: 0 | K69: https://www.youtube.com/watch?v=KMhlovvuqDg | L69: 28000 | M69: 【スカッとする話】13億の資産を築いた夫の葬儀後、通帳と印鑑を盗んだ義両親「3000万の家買っちゃったw」それを聞いてお腹を抱えて大爆笑→私「御愁傷さまw」実は...【スカッと】【朗読】
A70: 69 | D70: 468 Ungthuphoi | E70: https://www.youtube.com/channel/UChMTaakDMyRJ8dYWT6dyj6A | F70: https://www.youtube.com/watch?v=KXFghHJtNeI | G70: 1 | H70: 2 | I70: 1 年前 | J70: 47 | K70: https://www.youtube.com/watch?v=wjCku8hnE4A | L70: 21000 | M70: 【スカッとする話】母に誘われ高級料亭へ行くと女性にプロポーズする夫「亡き妻の分まで君を幸せにする！」直後、普段温厚な母が立ち上がり、母「お隣いいですか？」結果w
A71: 70 | D71: 578 Nhumotbong | E71: https://www.youtube.com/channel/UC0biqKicwkA9gYrdBBgU1-w | F71: https://www.youtube.com/watch?v=ZMKLsP9ebxU | G71: 1 | H71: 3 | I71: 1 年前 | J71: 1 | K71: https://www.youtube.com/watch?v=McNVTi5SXBU | L71: 95000 | M71: 【スカッとする話】姑との同居を勝手に決めた夫「引越しは済んだか？」私「うん！私の荷物も全部実家に送り終わったとこ」夫「え？実家？」結果w【修羅場】
A72: 71 | D72: 679 Moicaitay | E72: https://www.youtube.com/channel/UCbS2i6mY4rmoSoHWGu7uiYA | F72: https://www.youtube.com/watch?v=XM51nQV3pRg | G72: 1 | H72: 2 | I72: 1 年前 | J72: 0 | K72: https://www.youtube.com/watch?v=2ytRePzCVrE | L72: 60000 | M72: 【スカッとする話】私の出張中に勝手に姉と姪の引越し荷物を我が家に運び入れた夫「お前はずっと仕事してろw」私「はーい、こっちも勝手にするね」ハワイの豪邸に引越した結果w
A73: 72 | D73: Bonnie Denver | E73: https://www.youtube.com/channel/UCsdndA886timZqWK6_b0d0Q | F73: https://www.youtube.com/watch?v=mNNqKsGw3zk | G73: 1 | H73: 3 | I73: 1 年前 | J73: 0 | K73: https://www.youtube.com/watch?v=k6GWqtIXUlQ | L73: 42000 | M73: 【スカッとする話】台風の夜、5歳の孫からSOS「ママに家を追い出された！助けて」私「パパは？」孫「知らない女の人と出て行った」私「え？」キレた私は...
A74: 73 | D74: COLORS DECEIVE | E74: https://www.youtube.com/channel/UCytiIFYh1eDwUeCeeUdLqZQ | F74: https://www.youtube.com/watch?v=-y-Wocuo5FY | G74: 1 | H74: 2 | I74: 2 年前 | J74: 4734 | K74: https://www.youtube.com/watch?v=U9HQWEyzPVc | L74: 64000 | M74: 【スカッとする話】11億の資産を築いた父の葬儀後に夫が突然「父さんの遺産いくらあるんだ？w」私「3億通帳に入れてるよ」翌朝、離婚届けを置き通帳と印鑑を盗んだ夫が家に来て「あ、あの通帳って」
A75: 74 | D75: Dau Conhoen | E75: https://www.youtube.com/channel/UCbc3JRrwmaDW2_mYXitLGCg | F75: https://www.youtube.com/watch?v=gRDlO_YWtwA | G75: 1 | H75: 2 | I75: 2 年前 | J75: 353 | K75: https://www.youtube.com/watch?v=8Tm2R7t4MCc | L75: 140000 | M75: 【スカッとする話】家事、育児、介護、パートをこなし10年。ある日、出張後に夫が突然の土下座「お前の親友を妊娠させた！」親友「旦那は貰うから出てけw」私「喜んで！」3日後、血相変えた親友から鬼電がw
A76: 75 | D76: Deadpool Lool | E76: https://www.youtube.com/channel/UCCDbYtkLVK6W2f4MG5hSuBQ | F76: https://www.youtube.com/watch?v=gKvYOjL-TSQ | G76: 1 | H76: 2 | I76: 2 年前 | J76: 1 | K76: https://www.youtube.com/watch?v=jA4TTTeqo-M | L76: 120000 | M76: 【スカッとする話】私が年商500億の社長と知らない夫「時給941円の底辺は出てけw」連れ子「役立たずの母親バイバイw」私「じゃあ出ていきます」１ヶ月後、涙を流した夫から鬼電がw
A77: 76 | D77: Elliot Perry | E77: https://www.youtube.com/channel/UCu6sSOVx4IweXf0aPxIradQ | F77: https://www.youtube.com/watch?v=YI-bX_pqL4E | G77: 1 | H77: 2 | I77: 1 年前 | J77: 0 | K77: https://www.youtube.com/watch?v=N9NwywjCXnU | L77: 67000 | M77: 【スカッとする話】大学から10年付き合った婚約者「10代の嫁が良い！そろそろ婚活するからもう別れよ！」捨てられ3年後に婚約者から鬼電→私「あんた誰だっけ？」
A78: 77 | D78: FutureLens | E78: https://www.youtube.com/channel/UC1l4HieEbZPmgNoaCJdgHdw | F78: https://www.youtube.com/watch?v=CRlkbIQAxQk | G78: 1 | H78: 2 | I78: 4 週間前 | J78: 74 | K78: https://www.youtube.com/watch?v=6wF7ONOegQ0 | L78: 30000 | M78: 【スカッとする話】38歳で第一子を出産した私を捨て、19歳年下の不倫相手を優先した夫「可愛い子供が欲しかったな。お前との子はブスだから離婚で」18年後、娘と再会した夫が青ざめw【朗読】【スカッと】
A79: 78 | D79: Helen Chaney | E79: https://www.youtube.com/channel/UCknZc7rOLWhfFlVN8PKKzGQ | F79: https://www.youtube.com/watch?v=VN4pcX92erg | G79: 2 | H79: 3 | I79: 2 年前 | J79: 62 | K79: https://www.youtube.com/watch?v=9x2mRPOpvjQ | L79: 70000 | M79: 【スカッとする話】娘の結婚式当日に夫がいない…私「何してるの？式始まってるよ！」夫「悪い、緊急の仕事が入って！」私「…OK」1時間後、ある人物から電話を受けた夫が半狂乱にw
A80: 79 | D80: Hidalgo Jesus | E80: https://www.youtube.com/channel/UCmHPxolrDN4OJyWrR31soAA | F80: https://www.youtube.com/watch?v=jFXlACv0pLg | G80: 2 | H80: 3 | I80: 2 年前 | J80: 0 | K80: https://www.youtube.com/watch?v=2bkFoDUO1Qo | L80: 150000 | M80: 【スカッとする話】長男夫婦に初孫が生まれ出産祝いに行くと私だけカップ麺...長男嫁「家族の分しか無いですw」夫「...帰りますか」私「はい」直後、長男嫁に大惨事がw
... A106: 105 | D106: 人生の光と影 | E106: https://www.youtube.com/channel/UCYX4tsWpykTmtfNq_i36C_w | F106: https://www.youtube.com/watch?v=cYepYy4CPGU | G106: 1 | H106: 2 | I106: 5 日前 | J106: 87 | K106: https://www.youtube.com/watch?v=Ru27si_54MQ | L106: 300000 | M106: 【スカッとする話】結婚し幸せな日常を送る息子が急逝し13日後、私宛に亡き息子から手紙が届いた。手紙「俺の代わりに嫁に復讐を...」手紙で指定された場所に行った私は恐怖で震えだし...
A107: 106 | D107: 人生の小径、Love in later life | F107: https://www.youtube.com/watch?v=XdEKWgjOb-I | G107: 1 | H107: 2 | I107: 1 か月前 | J107: 9 | K107: https://www.youtube.com/watch?v=q3GnEwyCGbE | L107: 18000 | M107: 【スカッとする話】夫の手帳から愛人と隠し子との家族写真、更に離婚届が…。私「離婚したいから出せってことか！」即提出して夫の荷物を全て処分→黙って永久に姿を消した結果w
A108: 107 | D108: 人生の感動物語 | E108: https://www.youtube.com/channel/UCLq7Bngo0s5xFWKcyKaJHWA | F108: https://www.youtube.com/watch?v=2bnA0iWe1fM | G108: 6 | H108: 7 | I108: 2 か月前 | J108: 2 | K108: https://www.youtube.com/watch?v=NTuf2k99EWQ | L108: 270000 | M108: 【スカッとする話】体調不良でパートを早退し家に帰ると夫が親友と真っ最中...コッソリ二人の動画を撮影し親友の夫に送ってやった結果w
A109: 108 | D109: 人生の教訓 5696 | E109: https://www.youtube.com/channel/UChL0a6zTE7nHEavxEB0mGtQ | F109: https://www.youtube.com/watch?v=pE7R3YQKIW0 | G109: 1 | H109: 2 | I109: 3 週間前 | J109: 1 | K109: https://www.youtube.com/watch?v=39BPJNaibmM | L109: 75000 | M109: 【スカッとする話】父の会社を手伝って25年の私に夫「俺、来月引退することにした…会社は東京にいる長男に任せる」私「勝手にどうぞ。私今日でここ辞めるので」直後、父が半狂乱にw【朗読】【スカッと】
A110: 109 | D110: 人生の晩年5045 | E110: https://www.youtube.com/channel/UCRajns3nAnfDW1XFNGE8mjg | F110: https://www.youtube.com/watch?v=tH1-lLCCL1I | G110: 2 | H110: 4 | I110: 1 か月前 | J110: 6 | K110: https://www.youtube.com/watch?v=n-_5T-nb0dg | L110: 37000 | M110: 【スカッと】起業した夫を支えてきた私を裏切った夫「21歳のバイトを妊娠させた！離婚しで！」私「はーい、仕事も辞めるね！」夫「は？仕事は続けてくれよ」私「嫌よ。だってあのバイト...」
A111: 110 | D111: 人生逆転劇 | E111: https://www.youtube.com/channel/UChQ1QPCoCPRXlD5aqltcP2Q | F111: https://www.youtube.com/watch?v=iDMUfsZ73Bo | G111: 1 | H111: 2 | I111: 1 か月前 | J111: 27 | K111: https://www.youtube.com/watch?v=zb8EIRbjwZc | L111: 29000 | M111: 【スカッと総集編】妊娠した私を捨て21歳の浮気相手と再婚した社長の夫「彼女が妊娠したから離婚w」20年後、公園で元夫と再会すると…【スカッと】【スカッとする話】【修羅場】
A112: 111 | D112: 人生逆転噺5074 | E112: https://www.youtube.com/channel/UCSE8UrVc2WuisTfaKPVRjGA | F112: https://www.youtube.com/watch?v=nPSLaGnDiuQ | G112: 1 | H112: 2 | I112: 1 か月前 | J112: 1 | K112: https://www.youtube.com/watch?v=xZkf_P7X0BY | L112: 98000 | M112: 【スカッとする話】兄夫婦の出産祝いで父親と家を訪ねると父「今すぐ帰る！車を出せ！」慌てる父に理由を訪ねると、父「バックミラー見てみろ」私「え？」【朗読】【スカッと】
A113: 112 | D113: 今日の物語 | E113: https://www.youtube.com/channel/UCPXh5v9VEouZRWDFnMm2RNg | F113: https://www.youtube.com/watch?v=41IKF-y9FF4 | G113: 1 | H113: 2 | I113: 3 か月前 | J113: 150 | K113: https://www.youtube.com/watch?v=Mpi2bhYFSsQ | L113: 140000 | M113: 【スカッとする話】私が毎日12時間、義父の介護をしていると知らない夫「離婚しよう…お前と一緒はもう限界…」私「本当にいいの？」夫「当然w」→介護負担を伝えず即離婚して姿を消すと…w【朗読】【スカッと】
A114: 113 | D114: 午後の茶室5033 | E114: https://www.youtube.com/channel/UCAY-Kr81JdEZjsie9IiR_bw | F114: https://www.youtube.com/watch?v=c5j-gRh8bBE | G114: 1 | H114: 2 | I114: 3 週間前 | J114: 136 | K114: https://www.youtube.com/watch?v=bDw-dlei5Gk | L114: 46000 | M114: 【スカッと総集編】私が夫の入院費を払ってると知らず新居に引越した夫の連れ子「いつまで寄生虫するの？w」私「じゃ出てく」連れ子だけ残し1億の豪邸に引越した結果w
A115: 114 | D115: 嘘と温もり 5646 | E115: https://www.youtube.com/channel/UCxtvYnyBSRQBeUoKt9cvsmw | F115: https://www.youtube.com/watch?v=VGZ8u9KN8Vs | G115: 1 | H115: 2 | I115: 3 週間前 | J115: 0 | K115: https://www.youtube.com/watch?v=xyoQNySkFhc | L115: 100000 | M115: 【スカッとする話】私の事が大嫌いな長男嫁「ウチの冠婚葬祭に義両親は絶対来ないで。嫌なら離婚する」私「いいけど、アナタ本当に大丈夫？後悔するよ？」長男嫁「しねぇよw二度と連絡してくんなw」→数ヶ月後w
...

Sheet ラウンド1
A1: No. | B1: 申請日 | C1: 削除確認 | D1: 順位 | E1: チャンネル名 | F1: チャンネルURL | G1: 転載動画URL | H1: 一致率 | I1: 転載の投稿 | J1: 転載の再生数 | K1: 元動画URL | L1: 元動画の再生数 | M1: 元タイトル | N1: メモ
A2: 1 | D2: 1 | E2: 藤田 七海 | F2: https://www.youtube.com/channel/UCe0KTxGVR84qUjkAHQb-wGg | G2: https://www.youtube.com/watch?v=H3NTQ4PrQQY | H2: 1 | I2: 2 週間前 | J2: 54 | K2: https://www.youtube.com/watch?v=dOy6I1JE_yY | L2: 30000 | M2: 【スカッとする話】私の退職金をやたら気にする夫「いくら貰ったの？」私「口座に2000万入った！」翌日、カードを手に夫が失踪。私（計画通りw）実は【朗読】【スカッと】
A3: 2 | D3: 2 | E3: スカッと物語 | F3: https://www.youtube.com/channel/UCLz5UoQMIAja9LyZIOCYmQg | G3: https://www.youtube.com/watch?v=od3pGdQwxPk | H3: 1 | I3: 8 日前 | J3: 0 | K3: https://www.youtube.com/watch?v=IsPanDg1vH0 | L3: 28000 | M3: 【スカッとする話】娘の葬儀に愛人を連れてきた婿「最期に間に合わなくて残念w」愛人「遺産2億は私達が相続ねw」私「…ですってw」夫「助かるなw」愛人「え？」実はw【朗読ドラマ】【朗読】【スカッと】
A4: 3 | D4: 3 | E4: 出る杭は打たれる | F4: https://www.youtube.com/channel/UCAmIDIbiOxKA9YSVK0aYSZQ | G4: https://www.youtube.com/watch?v=eO55IR5xYH8 | H4: 1 | I4: 2 か月前 | J4: 0 | K4: https://www.youtube.com/watch?v=OJkzN_P6Tys | L4: 43000 | M4: 【スカッとする話】義母の私にだけ引越し先を教えない長男嫁「他人に住所は教えませんw今後一切関わらないでくださいw」1ヶ月後、長男嫁が病気で緊急手術→他人なので執刀医を辞退した結果w
A5: 4 | D5: 4 | E5: 良い話 | F5: https://www.youtube.com/channel/UCSrk1OzKlw4sCvRbksLDgcQ | G5: https://www.youtube.com/watch?v=BgwIu7GjpsA | H5: 1 | I5: 5 日前 | J5: 0 | K5: https://www.youtube.com/watch?v=p9EJ4XSEiOU | L5: 33000 | M5: 【スカッとする話】夫を略奪した美人同級生から結婚式の招待状が届くと、祖父「バァさんと2人で行く」祖母「地獄を見せてくるわ」普段温厚な祖父母がこの後...w【スカッと】【朗読】【修羅場】
A6: 5 | D6: 5 | E6: 家庭の真実 5497 | F6: https://www.youtube.com/channel/UCqzVZHS7_AHD3WczZdnOkwg | G6: https://www.youtube.com/watch?v=DBMjSadqY8E | H6: 1 | I6: 3 週間前 | J6: 30 | K6: https://www.youtube.com/watch?v=lRIrN83xkSc | L6: 62000 | M6: 【スカッとする話】私の車のアクセルにこっそり手を加える夫。私（知らないふりしよw）翌日、車を義両親に貸し出すと、夫「ま、待ってくれ…」実はw【朗読】【スカッと】
A7: 6 | D7: 6 | E7: スカッとストーリー 5006 | F7: https://www.youtube.com/channel/UC1x3I0LM2SzXkpn57uaFuQA | G7: https://www.youtube.com/watch?v=7UfS_a8A8SY | H7: 1 | I7: 1 か月前 | J7: 66 | K7: https://www.youtube.com/watch?v=YYnTTQ_3WI8 | L7: 59000 | M7: 【スカッとする話】妹の代わりに田舎の猟師に嫁いだ私「今日の夕飯は鹿肉？」夫「いや、これで好きな物食べて」10万円を手渡された私…→夫の正体を知った妹が半狂乱にw【朗読】【スカッと】
A8: 7 | D8: 7 | E8: 嫁ゴコロ逆転朗読館 | F8: https://www.youtube.com/channel/UCQDSjWHn0tvkuVZav4jZnXQ | G8: https://www.youtube.com/watch?v=sn9gV9SEkus | H8: 1 | I8: 6 日前 | J8: 0 | K8: https://www.youtube.com/watch?v=00HSG0Knh3I | L8: 17000 | M8: 【スカッとする話】70歳を過ぎ夫と別居中の私。40年もの間、夫は冷酷だった。ある日、夫の手帳を開いた瞬間、全てを理解し涙が溢れ…【朗読】【スカッと】
A9: 8 | D9: 8 | E9: 読書室【スカッとする話】 | F9: https://www.youtube.com/channel/UCjQd7ZVm5BPbGpB_V9B6kgQ | G9: https://www.youtube.com/watch?v=ykrbCE8A45A | H9: 1 | I9: 1 年前 | J9: 2 | K9: https://www.youtube.com/watch?v=RNWUvpjXeTw | L9: 22000 | M9: 【スカッと】私の子供が夫の上司と瓜二つ。夫「浮気してたな！離婚だ！」義母「アバズレは今すぐ出てけw」13年後、夫と義母と再会すると二人は半狂乱。だって娘は…
A10: 9 | D10: 9 | E10: 憂鬱よりスカッと | F10: https://www.youtube.com/channel/UC8bvniIkSPPf_5ELr1VNZCQ | G10: https://www.youtube.com/watch?v=EbCFdI1mcDA | H10: 1 | I10: 2 年前 | J10: 100 | K10: https://www.youtube.com/watch?v=VyoXxeYV0Ag | L10: 37000 | M10: 【スカッとする話】家事、育児、仕事をこなし夫と30年間連れ添った私に夫が突然の土下座「愛人が妊娠したから再婚する。離婚してくれ」私「はーい、ではさようなら」1週間後、半狂乱の夫から39件の鬼電がw
A11: 10 | D11: 10 | E11: とする話 | F11: https://www.youtube.com/channel/UC-1KoQRWd1ijwgKpAmRTQ7A | G11: https://www.youtube.com/watch?v=E9MMt25o2Es | H11: 1 | I11: 1 年前 | J11: 73 | K11: https://www.youtube.com/watch?v=w3t-NBVK2CU | L11: 31000 | M11: 【スカッとする話】結婚式当日に夫から突然の電話。夫「みんな集まってるぞ！早く来い！」私「え？なに言ってるの？」たった今終わったと伝えると…
A12: 11 | D12: 11 | E12: Dima Tomashevich | F12: https://www.youtube.com/channel/UCkfiH3lPVPodePE4eNSDpWg | G12: https://www.youtube.com/watch?v=SRmU4BFmMfU | H12: 1 | I12: 2 年前 | J12: 0 | K12: https://www.youtube.com/watch?v=xGHuS24cdnQ | L12: 16000 | M12: 【スカッとする話】夫が亡くなり葬式後、更に最愛の長男と孫まで亡くした私に長男嫁「遺産は私が貰うからババァも逝けw」と深夜に家を追い出された。公園で号泣してると、懐かしい声が聞こえ振り返ると...
A13: 12 | D13: 12 | E13: さあ、どうぞ | F13: https://www.youtube.com/channel/UCG-XF2tttCtNESz__p6GQ7w | G13: https://www.youtube.com/watch?v=EoPGSTdsArk | H13: 1 | I13: 2 か月前 | J13: 1 | K13: https://www.youtube.com/watch?v=jtzUWcGh5y8 | L13: 11000 | M13: 【スカッとする話】私の夫を奪ったママ友「医者の旦那さん奪っちゃったｗ赤ちゃんできたし豪華挙式するねｗ」私「結婚したことないですけど？」ママ友「え？」結果ｗ
... A18: 17 | D18: 17 | E18: 義家族スカッと物語帳 | F18: https://www.youtube.com/channel/UCIZ41RBpQd7wBp_oOTGv1zw | G18: https://www.youtube.com/watch?v=CLwUPWOMYZM | H18: 1 | I18: 6 日前 | J18: 0 | K18: https://www.youtube.com/watch?v=KVKExhX2jn4 | L18: 33000 | M18: 【スカッとする話】財布を届けにきた私に気づかない夫「嫁は何も疑ってないよw今夜もまた会えるねw」夫の正体を知り私の愛は消滅しw【朗読】【スカッと】
A19: 18 | D19: 18 | E19: 静かな夜の物語、雨の中の記憶 | G19: https://www.youtube.com/watch?v=hKi2-HjQLs0 | H19: 1 | I19: 2 週間前 | J19: 0 | K19: https://www.youtube.com/watch?v=Yrtj6pTpQ5A | L19: 100000 | M19: 【スカッと総集編】家事、育児、介護、パートをこなし15年。私「もう限界。実家に帰ります」夫「はぁ？ガキの面倒は？飯は？帰るなら離婚届書いてけ！」→速提出して両親に離婚報告すると涙を流した夫が家に来て…
A20: 19 | D20: 19 | E20: Noah Qumi | F20: https://www.youtube.com/channel/UCH4l3-r5NgR2RlKdoRwfzAw | G20: https://www.youtube.com/watch?v=MHsVbMKecBY | H20: 1 | I20: 7 日前 | J20: 0 | K20: https://www.youtube.com/watch?v=blo_a56_T1U | L20: 370000 | M20: 【スカッとする話】愛人に夫を奪われた私。2人「すまん、離婚してくれ…」離婚届が置かれた瞬間、即サインし夫を譲ると、相手弁護士がガタガタ震え出しw【朗読】【スカッと】
A21: 20 | D21: 20 | E21: Shinji Datの人生物語 | F21: https://www.youtube.com/channel/UCpdX_bFCePsYvPWZAMQoaeg | G21: https://www.youtube.com/watch?v=FiGEQo_QLoY | H21: 1 | I21: 2 か月前 | J21: 11 | K21: https://www.youtube.com/watch?v=gqjIGgB7rlA | L21: 40000 | M21: 【スカッとする話】夫「俺の年金は1円もやらん」40年間夫を支えてきたのに、他人のように突き放された私（もう我慢しなくていっかw）→翌日、なぜか夫が泣き叫びw【朗読】【スカッと】
A22: 21 | D22: 21 | E22: スカッとする話 5020 | F22: https://www.youtube.com/channel/UCAG5eZR0aJpGuShtjtimSEg | G22: https://www.youtube.com/watch?v=-FQjdMNh2gM | H22: 1 | I22: 4 週間前 | J22: 43 | K22: https://www.youtube.com/watch?v=gVrVwssbXow | L22: 28000 | M22: 【感動する話】親に捨てられた中1の私に弁当屋の夫婦「これお食べ」空腹の私を助けてくれた老夫婦。20年後、社長になった私が再訪問→張り紙の一文で泣き崩れ…【朗読】
A23: 22 | D23: 22 | E23: 人生の光と影 | F23: https://www.youtube.com/channel/UCYX4tsWpykTmtfNq_i36C_w | G23: https://www.youtube.com/watch?v=8AmSKMrlaRQ | H23: 1 | I23: 8 日前 | J23: 161 | K23: https://www.youtube.com/watch?v=ZTng_6NCKl8 | L23: 60000 | M23: 【スカッとする話】親代わりに育てた弟の結婚式でタキシードを着た弟が1人ポツン。弟「結婚は嘘でドッキリって…」直後、普段温厚な夫が新婦一族に電話。夫「出資1億はキャンセルで」新婦一族「え？」【朗読】
A24: 23 | D24: 23 | E24: 美しい木 | F24: https://www.youtube.com/channel/UCKDhvWl0boDNeo65NQzjbOg | G24: https://www.youtube.com/watch?v=xAHW3dG1V5M | H24: 1 | I24: 3 か月前 | J24: 0 | K24: https://www.youtube.com/watch?v=3WJaWicyrhk | L24: 25000 | M24: 【スカッとする話】長男夫婦の結婚式の帰宅中、突然激怒する夫「犯罪者のクズとは離婚！毎月の仕送り5万盗んでただろ！」 私「承知しました...」 即離婚して仕送り辞めた結果w【スカッと】
A25: 24 | D25: 24 | E25: TINA SHTIBKO | F25: https://www.youtube.com/channel/UCIQbb4FNm2BhP5GfSTbrQ4w | G25: https://www.youtube.com/watch?v=LFh5HyZqSaY | H25: 1 | I25: 2 年前 | J25: 0 | K25: https://www.youtube.com/watch?v=4XaTm2Lo-tc | L25: 51000 | M25: 【スカッとする話】長男が結婚し実家で同居すると、長男嫁「狭いので出てって下さいw」我が家を追い出され1ヶ月後、私の新居を見にきた長男嫁「こ、この家って」
A26: 25 | D26: 25 | E26: フィクション 5634 | F26: https://www.youtube.com/channel/UCtx1aitp-eTJhv2c94bnBZQ | G26: https://www.youtube.com/watch?v=1dPUOOQoIgw | H26: 1 | I26: 3 週間前 | J26: 211 | K26: https://www.youtube.com/watch?v=K7QGPSQED7o | L26: 30000 | M26: 【感動する話】離婚前夜、夫との最後の晩餐。料亭で夫を待ち続けたが、メールの返信もなく現れない。その時、突然私に声をかけた店主「実は、ご主人が…」【朗読】
A27: 26 | D27: 26 | E27: 泥だらけの絆 5655 | F27: https://www.youtube.com/channel/UCdyvc7k9wPzVO9X62aCvguQ | G27: https://www.youtube.com/watch?v=AXXpmLXnPFo | H27: 1 | I27: 13 日前 | J27: 1 | K27: https://www.youtube.com/watch?v=qNSSnNaMxrs | L27: 80000 | M27: 【スカッとする話】私1人で育てた息子の顔合わせで、なぜか私たちだけお茶漬け…義家族「貧乏人は好きだろ？w」直後、私の存在に気づいた義兄「俺たちの人生終了だ…」【朗読】【スカッと】
A28: 27 | D28: 27 | E28: Bonnie Denver | F28: https://www.youtube.com/channel/UCsdndA886timZqWK6_b0d0Q | G28: https://www.youtube.com/watch?v=gw_bZgF_vcw | H28: 1 | I28: 1 年前 | J28: 4 | K28: https://www.youtube.com/watch?v=tOHZbuZysA4 | L28: 74000 | M28: 【スカッとする話】医者一族の婚約者と結婚挨拶に行くと私達の席だけない。義母「片親の貧乏人とは婚約破棄w」母「ではおたくの病院潰すわ」義家族「え？」
A29: 28 | D29: 28 | E29: 心温まるストーリー 4989 | F29: https://www.youtube.com/channel/UCS-VuYFB_DXsDhPHAzUS0JA | G29: https://www.youtube.com/watch?v=qJ8No7XGqYQ | H29: 1 | I29: 1 か月前 | J29: 98 | K29: https://www.youtube.com/watch?v=qNSSnNaMxrs | L29: 80000 | M29: 【スカッとする話】私1人で育てた息子の顔合わせで、なぜか私たちだけお茶漬け…義家族「貧乏人は好きだろ？w」直後、私の存在に気づいた義兄「俺たちの人生終了だ…」【朗読】【スカッと】
A30: 29 | D30: 29 | E30: Jamison Abraham | F30: https://www.youtube.com/channel/UCcUsK23eqHw3ZQA5HjspM9Q | G30: https://www.youtube.com/watch?v=Nududo1BLfA | H30: 1 | I30: 1 年前 | J30: 0 | K30: https://www.youtube.com/watch?v=Mi69PEXjWFc | L30: 35000 | M30: 【スカッと】365日間、私を無視し続けた年収1000万の夫「誰のおかげで生きてると思ってる！文句あるなら離婚して出てけw」私「後悔しない？」夫「しねぇよw」3日後、夫は会社をクビにw
A31: 30 | D31: 30 | E31: サヨナラの選択4848 | F31: https://www.youtube.com/channel/UCiDg2Vs1LHy6qIiV6ilje1A | G31: https://www.youtube.com/watch?v=ks7lwFCnjLM | H31: 1 | I31: 3 週間前 | J31: 0 | K31: https://www.youtube.com/watch?v=Y4k29xHFHUY | L31: 33000 | M31: 【スカッとする話】デパートでバイトする私に会長夫人「私を誰だと思ってるの？ここの会長の夫人様よ！」私「で？」夫人「もういいお前クビ！」直後、会長夫人は全てを失い…w【朗読】【スカッと】
... A38: 37 | D38: 37 | E38: 痛快!!怒りのスカッとチャンネル【スカッと朗読】 | F38: https://www.youtube.com/channel/UC96mO8pXAaiP70V7KUjVHqg | G38: https://www.youtube.com/watch?v=4_x4CtcujZ0 | H38: 1 | I38: 1 年前 | J38: 39 | K38: https://www.youtube.com/watch?v=bI91wh-7IMg | L38: 190000 | M38: 【スカッとする話】孫の七五三のお祝いに親戚一同と行くと私だけ席がない...長男嫁「他人の席は無いから立ってればw」私「じゃ帰るか」親戚一同「うん」全員で帰宅した結果w
A39: 38 | D39: 38 | E39: 雨の中の記憶、雨の中の記憶 | G39: https://www.youtube.com/watch?v=D7M2p9ALM9c | H39: 1 | I39: 3 週間前 | J39: 19 | K39: https://www.youtube.com/watch?v=KKEWop4fNrk | L39: 66000 | M39: 【スカッと総集編】私が総資産が28億の社長令嬢と知らず私を裏切り職場の美人同僚と再婚した夫「美人同僚と再婚するから離婚w」同僚「子供は1人で頑張れｗ」私「はーい」1ヶ月後、夫達から鬼電がw
A40: 39 | D40: 39 | E40: スカっとゼミ!! | F40: https://www.youtube.com/channel/UC9Hd679L2faWD0aJQHeAlrA | G40: https://www.youtube.com/watch?v=tc-9FGKPWTs | H40: 0.96 | I40: 1 年前 | J40: 7509 | K40: https://www.youtube.com/watch?v=VrctjOjY0Ts | L40: 88000 | M40: 【スカッとする話】単身赴任中の私に夫から速達で離婚届…夫「息子も離婚して欲しいってw」私（やっと自由になれるw）大喜びして離婚届を提出し家を売り払い更地にするとw
A41: 40 | D41: 40 | E41: スカッと成敗ストーリー | F41: https://www.youtube.com/channel/UC1iIGo491nSYyJ_AsgmPzyw | G41: https://www.youtube.com/watch?v=cmr_Wm_l0r0 | H41: 1 | I41: 2 か月前 | J41: 0 | K41: https://www.youtube.com/watch?v=NskvXTGiyMY | L41: 34000 | M41: 【スカッとする話】私がグループ13社の社長と知らず、母の葬儀後に銀行員の夫「相続少ねぇなw離婚でw」即離婚届を提出し夫の銀行へ→私「700億の法人口座は解約で」
A42: 41 | D42: 41 | E42: 時を越える話 | F42: https://www.youtube.com/channel/UC_n9gc1na-2QpFv6TPInL3w | G42: https://www.youtube.com/watch?v=ISJkWfnE524 | H42: 1 | I42: 3 週間前 | J42: 3159 | K42: https://www.youtube.com/watch?v=ZobJWKrmIzQ | L42: 77000 | M42: 【スカッとする話】娘の結婚式に愛人と共に現れた夫「彼女にも座らせてあげて」私は黙って愛人に席を譲った直後、グループ10社を束ねる新郎父「会長、お久しぶりです」【朗読】【スカッと】
A43: 42 | D43: 42 | E43: 涙の向こう側 | F43: https://www.youtube.com/channel/UCOXAYjsxUMpublA1yS1ATIA | G43: https://www.youtube.com/watch?v=SwLud5WJ-9Q | H43: 1 | I43: 8 日前 | J43: 673 | K43: https://www.youtube.com/watch?v=7b4pVxD6-XQ | L43: 18000 | M43: 【スカッとする話】私「もう限界…出ていきます」夫「家事と介護は嫁の仕事！責任果たせないなら離婚！」お望み通り離婚届を置いて姿を消すと→半狂乱の夫から鬼電がw【朗読】【スカッと】
A44: 43 | D44: 43 | E44: 老いの詩 | F44: https://www.youtube.com/channel/UClKj-HO63gh7qxtT7M0czEQ | G44: https://www.youtube.com/watch?v=pQKMo5JuRYs | H44: 1 | I44: 1 か月前 | J44: 5 | K44: https://www.youtube.com/watch?v=YYnTTQ_3WI8 | L44: 59000 | M44: 【スカッとする話】妹の代わりに田舎の猟師に嫁いだ私「今日の夕飯は鹿肉？」夫「いや、これで好きな物食べて」10万円を手渡された私…→夫の正体を知った妹が半狂乱にw【朗読】【スカッと】
A45: 44 | D45: 44 | E45: Ivan Ilencow | F45: https://www.youtube.com/channel/UC6IzQHpKzqIt1DgjPouEefQ | G45: https://www.youtube.com/watch?v=9GauLOUX3QM | H45: 1 | I45: 2 年前 | J45: 2 | K45: https://www.youtube.com/watch?v=CTeggEwk2Nc | L45: 28000 | M45: 【スカッとする話】妊婦の私が倒れて入院するとワインをぶっかけ海外旅行に行く夫「帰るまでに産んでおけよ！」無視した私に夫がワインを投げるも当たって失神したのは...【修羅場】【スカッと】
A46: 45 | D46: 45 | E46: Legacy Apollo | F46: https://www.youtube.com/channel/UC2YwIXq-utTkNLQgcRVloyQ | G46: https://www.youtube.com/watch?v=c0b7OwI4zCw | H46: 1 | I46: 2 年前 | J46: 175 | K46: https://www.youtube.com/watch?v=-WjRVa4jNLk | L46: 59000 | M46: 【スカッとする話】73歳の誕生日に長男夫婦がくれた10万円の時計をゴミ箱に捨てた私に夫「長男と長男嫁さんに土下座して謝れ！」私「これ見ても同じこと言える？」夫「え？」実は…【修羅場】
A47: 46 | D47: 46 | E47: Pendelton Gideon | F47: https://www.youtube.com/channel/UCIRVjzjmTHwXA3X81dpyNeQ | G47: https://www.youtube.com/watch?v=yAg-ur38iSY | H47: 1 | I47: 1 年前 | J47: 2 | K47: https://www.youtube.com/watch?v=tOHZbuZysA4 | L47: 74000 | M47: 【スカッとする話】医者一族の婚約者と結婚挨拶に行くと私達の席だけない。義母「片親の貧乏人とは婚約破棄w」母「ではおたくの病院潰すわ」義家族「え？」
A48: 47 | D48: 47 | E48: Павел **** | F48: https://www.youtube.com/channel/UCSPg9ALk7YwnsqACClpErGg | G48: https://www.youtube.com/watch?v=iKlAkSZVtcE | H48: 1 | I48: 2 年前 | J48: 0 | K48: https://www.youtube.com/watch?v=EIrAyCZzwiI | L48: 34000 | M48: 【スカッとする話】40度の高熱の私から財布とクレカを奪った長男嫁「はい、氷水w帰るまでに治して下さいねｗ」バケツで氷水をかけられ気絶した…3日後、私はご機嫌に帰宅した長男嫁に...
A49: 48 | D49: 48 | E49: 人生スカッと朗読館 | F49: https://www.youtube.com/channel/UChTkZ7g3oCCQG3XSqe69LWQ | G49: https://www.youtube.com/watch?v=qsjIpApuEeQ | H49: 1 | I49: 5 日前 | J49: 0 | K49: https://www.youtube.com/watch?v=hi2PAohyTkU | L49: 20000 | M49: 【スカッとする話】夫の出張中、オウムを任された私。何気なくオウムに話しかけると、オウム「嫁にはバレてないよ」不審に思い夫の部屋を開けた。→直後、私は顔面蒼白に…【朗読ドラマ】【朗読】【スカッと】
A50: 49 | D50: 49 | E50: 夜の語り部5056 | F50: https://www.youtube.com/channel/UCEvaB4r-6y7tj3UAoMEdqXA | G50: https://www.youtube.com/watch?v=bQ7ZCEsAHqU | H50: 1 | I50: 1 か月前 | J50: 1 | K50: https://www.youtube.com/watch?v=t9x4VmiCRI4 | L50: 43000 | M50: 【スカッとする話】親代わりで育てた妹の結婚式で、着物姿の妹が式場に1人ポツン…義家族「嘘に決まってるじゃんw」私「なら契約も嘘か！了解」義家族「え？」実はw【朗読】【スカッと】
...

Sheet ラウンド2
A1: No. | B1: 申請日 | C1: 削除確認 | D1: 順位 | E1: チャンネル名 | F1: チャンネルURL | G1: 転載動画URL | H1: 一致率 | I1: 転載の投稿 | J1: 転載の再生数 | K1: 元動画URL | L1: 元動画の再生数 | M1: 元タイトル | N1: メモ
A2: 1 | D2: 1 | E2: 藤田 七海 | F2: https://www.youtube.com/channel/UCe0KTxGVR84qUjkAHQb-wGg | G2: https://www.youtube.com/watch?v=MCdA3DExAwI | H2: 1 | I2: 2 週間前 | J2: 3 | K2: https://www.youtube.com/watch?v=ZobJWKrmIzQ | L2: 77000 | M2: 【スカッとする話】娘の結婚式に愛人と共に現れた夫「彼女にも座らせてあげて」私は黙って愛人に席を譲った直後、グループ10社を束ねる新郎父「会長、お久しぶりです」【朗読】【スカッと】
A3: 2 | D3: 2 | E3: スカッと物語 | F3: https://www.youtube.com/channel/UCLz5UoQMIAja9LyZIOCYmQg | G3: https://www.youtube.com/watch?v=Ef-RDmTY9Jk | H3: 1 | I3: 7 日前 | J3: 0 | K3: https://www.youtube.com/watch?v=DEqKKzP1pB4 | L3: 21000 | M3: 【スカッとする話】通院費1万すら拒絶した息子夫婦「年金から払えば？w」翌日、家の名義を変え姿を消すと、大号泣の2人から大量着信が…w【朗読ドラマ】【朗読】【スカッと】
A4: 3 | D4: 3 | E4: 出る杭は打たれる | F4: https://www.youtube.com/channel/UCAmIDIbiOxKA9YSVK0aYSZQ | G4: https://www.youtube.com/watch?v=1cday0ktFEQ | H4: 1 | I4: 2 か月前 | J4: 0 | K4: https://www.youtube.com/watch?v=DeIUkxQ3Yjg | L4: 10000 | M4: 【スカッとする話】生まれた息子が夫に似てない。夫「浮気してたな？離婚だ！」義父「今すぐ出てけアバズレが」10年後、夫と義父と遭遇すると2人が発狂。だって息子は…
A5: 4 | D5: 4 | E5: 良い話 | F5: https://www.youtube.com/channel/UCSrk1OzKlw4sCvRbksLDgcQ | G5: https://www.youtube.com/watch?v=_NmgMfK7eX0 | H5: 1 | I5: 5 日前 | J5: 0 | K5: https://www.youtube.com/watch?v=s8zl0VxtC2k | L5: 63000 | M5: 【スカッと総集編】離婚から２週間で再婚した元夫「家柄、性格ともに最高の嫁w」夫の新しい嫁を見た瞬間、私は思わず大爆笑www→だってその嫁は…w
A6: 5 | D6: 5 | E6: 家庭の真実 5497 | F6: https://www.youtube.com/channel/UCqzVZHS7_AHD3WczZdnOkwg | G6: https://www.youtube.com/watch?v=RoD3ADzOkEQ | H6: 1 | I6: 4 週間前 | J6: 21 | K6: https://www.youtube.com/watch?v=AW46gN91lmo | L6: 18000 | M6: 【スカッとする話】孫の合格祝いで義実家に行くと私と夫だけわさびのみだった…義兄「もらえるだけ光栄だろw」私「ありがたく頂きますね」帰宅後、悶絶し涙目の義兄が…w【朗読】【スカッと】
A7: 6 | D7: 6 | E7: スカッとストーリー 5006 | F7: https://www.youtube.com/channel/UC1x3I0LM2SzXkpn57uaFuQA | G7: https://www.youtube.com/watch?v=7p73mp_ivBs | H7: 1 | I7: 1 か月前 | J7: 89 | K7: https://www.youtube.com/watch?v=Jrhwc49ujEM | L7: 68000 | M7: 【スカッとする話】貧乏なフリしてお見合いに行くと男性社長「仕事は何してるの？」私「内職です…（フラれたな）」直後、伝票に書いた私の字を見た彼「僕と付き合って」実は…【朗読】【スカッと】
A8: 7 | D8: 7 | E8: 嫁ゴコロ逆転朗読館 | F8: https://www.youtube.com/channel/UCQDSjWHn0tvkuVZav4jZnXQ | G8: https://www.youtube.com/watch?v=JIMx_juz-_s | H8: 1 | I8: 6 日前 | J8: 0 | K8: https://www.youtube.com/watch?v=Lz3rc2N2XhM | L8: 47000 | M8: 【スカッとする話】正月、帰省の新幹線で、妊娠中の私を立ち席にした夫は「腰が痛い」と1人グリーン車へ。愛人の元へ向かったと知った私は、何も告げず新大阪で姿を消すとw【朗読】【スカッと】
A9: 8 | D9: 8 | E9: 読書室【スカッとする話】 | F9: https://www.youtube.com/channel/UCjQd7ZVm5BPbGpB_V9B6kgQ | G9: https://www.youtube.com/watch?v=9zs6le8kFYk | H9: 1 | I9: 1 年前 | J9: 1 | K9: https://www.youtube.com/watch?v=7msH4kMIKYA | L9: 15000 | M9: 【スカッと】夫を略奪した妹の結婚式で妹「今日から私が社長夫人で〜すw社員は全員パシリよろしく〜w」直後、社員一同が大爆笑w→私（社長は私なんだよな…w）
A10: 9 | D10: 9 | E10: 憂鬱よりスカッと | F10: https://www.youtube.com/channel/UC8bvniIkSPPf_5ELr1VNZCQ | G10: https://www.youtube.com/watch?v=WxOpFiBUsKQ | H10: 1 | I10: 2 年前 | J10: 68 | K10: https://www.youtube.com/watch?v=jpA_PiL1qKA | L10: 31000 | M10: 【スカッとする話】私「もう限界！実家に帰ります！」実家帰省した私が家に帰ると私「ただい...ま？」机の上に記入済みの離婚届が...私「出せっていうから提出しよw」大喜びで市役所へ行った結果w
A11: 10 | D11: 10 | E11: とする話 | F11: https://www.youtube.com/channel/UC-1KoQRWd1ijwgKpAmRTQ7A | G11: https://www.youtube.com/watch?v=SBuY8D55Xp8 | H11: 1 | I11: 1 年前 | J11: 0 | K11: https://www.youtube.com/watch?v=H3HkNoT1qF0 | L11: 72000 | M11: 【スカッとする話】母が他界した直後、7歳の私を捨て職場の愛人と再婚した父「お前は目障りだから施設行けw」3か後、半狂乱の父から鬼電→私「私に父はいませんけど？」
A12: 11 | D12: 11 | E12: Dima Tomashevich | F12: https://www.youtube.com/channel/UCkfiH3lPVPodePE4eNSDpWg | G12: https://www.youtube.com/watch?v=JiYO5b0V6pU | H12: 1 | I12: 2 年前 | J12: 0 | K12: https://www.youtube.com/watch?v=3SjNRx445WM | L12: 31000 | M12: 【スカッとする話】家事に疲れて昼寝してた私に花瓶の水をぶっかけてきた長男嫁「私のおかげで暮らせてるのに…ちゃんとメシぐらい作れ！」私「無理。じゃあ出て行くわ」長男嫁「え？」
A13: 12 | D13: 12 | E13: さあ、どうぞ | F13: https://www.youtube.com/channel/UCG-XF2tttCtNESz__p6GQ7w | G13: https://www.youtube.com/watch?v=t74xjdInIKo | H13: 1 | I13: 2 か月前 | J13: 1 | K13: https://www.youtube.com/watch?v=ZJzIfS3DH88 | L13: 18000 | M13: 【スカッとする話】病気で盲目になった夫のため、365日ずっと料理を作る私に夫「味噌汁おいしかった！味噌変えた？」私は空っぽの鍋を見た瞬間、家中の鍵を全て交換し…
... A18: 17 | D18: 17 | E18: 義家族スカッと物語帳 | F18: https://www.youtube.com/channel/UCIZ41RBpQd7wBp_oOTGv1zw | G18: https://www.youtube.com/watch?v=SqxgbTS5sbk | H18: 1 | I18: 7 日前 | J18: 0 | K18: https://www.youtube.com/watch?v=wWt0dqnPt6g | L18: 65000 | M18: 【スカッとする話】38歳で両親に結婚を急かされ「相手はいる」と嘘をつくとイケメン上司「俺が恋人役するよ」1週間後、両親に会わせると父「まさか…こんな所で」実は【朗読】【スカッと】
A19: 18 | D19: 18 | E19: 静かな夜の物語、雨の中の記憶 | G19: https://www.youtube.com/watch?v=4sbyeBKVtv0 | H19: 1 | I19: 2 週間前 | J19: 0 | K19: https://www.youtube.com/watch?v=TKF2Pe7g2bE | L19: 49000 | M19: 【スカッとする話】4人の子供に囲まれ幸せな日常を送る夫が急逝し2週間後、私宛に夫から手紙が届いた「連れ子に隠れて読んでくれ...」手紙に記された場所へ行き同封の鍵で金庫を開けると...
A20: 19 | D20: 19 | E20: Noah Qumi | F20: https://www.youtube.com/channel/UCH4l3-r5NgR2RlKdoRwfzAw | G20: https://www.youtube.com/watch?v=0HyRkakDfNI | H20: 1 | I20: 7 日前 | J20: 1 | K20: https://www.youtube.com/watch?v=2meTtNT2fJ8 | L20: 250000 | M20: 【スカッとする話】母の手術費のためにバケモノ御曹司と婚約した私。父「すまんな…」結婚初日、別人の彼の姿に驚愕し…【朗読】【スカッと】
A21: 20 | D21: 20 | E21: Shinji Datの人生物語 | F21: https://www.youtube.com/channel/UCpdX_bFCePsYvPWZAMQoaeg | G21: https://www.youtube.com/watch?v=5SfD5lmv8GY | H21: 1 | I21: 2 か月前 | J21: 13 | K21: https://www.youtube.com/watch?v=uYt37nxwb0o | L21: 18000 | M21: 【スカッとする話】私の資産が9億あると知らず社長令嬢の愛人と再婚した元夫と再会「生活保護の貧乏人じゃんw元気？w」私「は？誰と勘違いしてるの？」真実を伝えると元夫が半狂乱にw【スカッと】【朗読】
A22: 21 | D22: 21 | E22: スカッとする話 5020 | F22: https://www.youtube.com/channel/UCAG5eZR0aJpGuShtjtimSEg | G22: https://www.youtube.com/watch?v=tiOlfcaKAJE | H22: 1 | I22: 1 か月前 | J22: 64 | K22: https://www.youtube.com/watch?v=gBmPsDEOoUs | L22: 97000 | M22: 【スカッとする話】結婚直前で逃げた姉の代わりに田舎の農家に嫁いだ私。私「私も手伝おうか？」夫「君は家でゆっくりしてて」翌朝、口座に1000万円…実はw【朗読】【スカッと】
A23: 22 | D23: 22 | E23: 人生の光と影 | F23: https://www.youtube.com/channel/UCYX4tsWpykTmtfNq_i36C_w | G23: https://www.youtube.com/watch?v=k8PCprhidvc | H23: 1 | I23: 8 日前 | J23: 111 | K23: https://www.youtube.com/watch?v=LMo-dxLN6Qc | L23: 37000 | M23: 【スカッとする話】12年前、私の夫を略奪し駆け落ちした長男嫁から連絡。長男嫁「旦那と久しぶりに帰るwあんたはトイレに隠れててw」私「はい…」→約束破ってトイレから飛び出すと…w【朗読】【スカッと】
A24: 23 | D24: 23 | E24: 美しい木 | F24: https://www.youtube.com/channel/UCKDhvWl0boDNeo65NQzjbOg | G24: https://www.youtube.com/watch?v=JaHSlsKxqLI | H24: 1 | I24: 3 か月前 | J24: 0 | K24: https://www.youtube.com/watch?v=SA1PcWksbus | L24: 38000 | M24: 【スカッとする話】5歳の娘の病気が判明した途端、私と娘を捨て愛人と消えた夫。9年後、娘のある秘密を知ると夫「迎えに来たぞ！パパと帰ろう」娘「え？誰このおじさん」夫「え？」
A25: 24 | D25: 24 | E25: TINA SHTIBKO | F25: https://www.youtube.com/channel/UCIQbb4FNm2BhP5GfSTbrQ4w | G25: https://www.youtube.com/watch?v=vH2vcM_uFO8 | H25: 1 | I25: 2 年前 | J25: 0 | K25: https://www.youtube.com/watch?v=l5MOnDUec8k | L25: 34000 | M25: 【スカッとする話】祖母と同居の長男夫婦に毎月25万の仕送りをする私が祖母の様子を見に行くと伝えると長男が激怒「何しにくる気だ！？今まで何もしなかったくせに！」私「は？」実は…
A26: 25 | D26: 25 | E26: フィクション 5634 | F26: https://www.youtube.com/channel/UCtx1aitp-eTJhv2c94bnBZQ | G26: https://www.youtube.com/watch?v=zjVmh756GWo | H26: 1 | I26: 3 週間前 | J26: 1324 | K26: https://www.youtube.com/watch?v=2ALPcxU2NE8 | L26: 33000 | M26: 【スカッとする話】自衛官の兄の結婚式に参加すると、義母「中卒の妹は一族の汚点w」直後、兄が義母の元に歩み寄り、兄「まだ妹の正体に気づかない？」義母「え？」【朗読】【スカッと】
A27: 26 | D27: 26 | E27: 泥だらけの絆 5655 | F27: https://www.youtube.com/channel/UCdyvc7k9wPzVO9X62aCvguQ | G27: https://www.youtube.com/watch?v=tk0adRpC7xI | H27: 1 | I27: 11 日前 | J27: 16 | K27: https://www.youtube.com/watch?v=ae1eDwWjrBU | L27: 76000 | M27: 【スカッとする話】親戚の集まりに私たち家族だけ招待しない義両親。義父「お前ら貧乏家族は不要w」私「わかりました…」家族全員で欠席しハワイ旅行行くと→大号泣の義父から鬼電がw【朗読】【スカッと】
A28: 27 | D28: 27 | E28: Bonnie Denver | F28: https://www.youtube.com/channel/UCsdndA886timZqWK6_b0d0Q | G28: https://www.youtube.com/watch?v=Lapb-z9pqnY | H28: 1 | I28: 1 年前 | J28: 1 | K28: https://www.youtube.com/watch?v=Utio_7T1lvM | L28: 54000 | M28: 【スカッとする話】11年介護した義父の葬儀後に義母「家政婦は用済み！出てけw」夫「離婚届書いて失せろw」私「分かった（全て計画通りw）」1ヶ月後、涙を流した夫と義母から鬼電がw
A29: 28 | D29: 28 | E29: 心温まるストーリー 4989 | F29: https://www.youtube.com/channel/UCS-VuYFB_DXsDhPHAzUS0JA | G29: https://www.youtube.com/watch?v=zZK_hwS9jv8 | H29: 1 | I29: 1 か月前 | J29: 72 | K29: https://www.youtube.com/watch?v=cVe3XmXeRuE | L29: 140000 | M29: 【スカッとする話】私が離婚届に署名すると、満面の笑みで大喜びする義家族。新しい嫁を迎えた1週間後、電気・ガス・水道が止まると急に義家族が焦り出しw【朗読】【スカッと】
A30: 29 | D30: 29 | E30: Jamison Abraham | F30: https://www.youtube.com/channel/UCcUsK23eqHw3ZQA5HjspM9Q | G30: https://www.youtube.com/watch?v=y8x7SoRM9mk | H30: 1 | I30: 1 年前 | J30: 0 | K30: https://www.youtube.com/watch?v=CNsn701Em6g | L30: 41000 | M30: 【スカッと】私が総資産19億と知らず子供の産めない私を捨て再婚した夫「欠陥品とは離婚ｗ家と車も俺が貰うｗ」私「いいよ！ 」→翌日、涙を流した夫から鬼電がw
A31: 30 | D31: 30 | E31: サヨナラの選択4848 | F31: https://www.youtube.com/channel/UCiDg2Vs1LHy6qIiV6ilje1A | G31: https://www.youtube.com/watch?v=iOzvYl0FjG0 | H31: 1 | I31: 2 週間前 | J31: 1 | K31: https://www.youtube.com/watch?v=yluothDtfeE | L31: 35000 | M31: 【スカッとする話】私の実家の庭に幼馴染の家を建てる夫。夫「貧乏だから助けてあげたい」私「それ本当に大丈夫？」真実を伝えると夫が震えだしw【朗読】【スカッと】
... A38: 37 | D38: 37 | E38: 痛快!!怒りのスカッとチャンネル【スカッと朗読】 | F38: https://www.youtube.com/channel/UC96mO8pXAaiP70V7KUjVHqg | G38: https://www.youtube.com/watch?v=agja1b2k0kA | H38: 1 | I38: 1 年前 | J38: 23 | K38: https://www.youtube.com/watch?v=hRCh_bWpcgg | L38: 100000 | M38: 【スカッとする話】私が義母の入院費を払ってると知らず新居に引っ越した夫「寄生虫は施設でもいけw」1億の高級施設に引越し入院費の支払も止めた結果w
A39: 38 | D39: 38 | E39: 雨の中の記憶、雨の中の記憶 | G39: https://www.youtube.com/watch?v=jzQ7tWnYBb4 | H39: 1 | I39: 3 週間前 | J39: 9 | K39: https://www.youtube.com/watch?v=c2AdQUXc1Hg | L39: 59000 | M39: 【スカッと総集編】入院した私に大量の塩をぶっかける長男嫁「このままあの世にいけwババァがいなくて最高w」キレた私は長男嫁への仕送りを停止→本当に帰らぬ人となった結果w
A40: 39 | D40: 39 | E40: スカっとゼミ!! | F40: https://www.youtube.com/channel/UC9Hd679L2faWD0aJQHeAlrA | G40: https://www.youtube.com/watch?v=DKzM1r5EGpw | H40: 0.83 | I40: 2 年前 | J40: 112 | K40: https://www.youtube.com/watch?v=6UWe8WooXpM | L40: 100000 | M40: 【スカッとする話】母子家庭で育てた長男の結婚式へ行くと私の席が無い...姑「貧乏人の席はありませんw」長男「帰ろっか..」私「うん...」義家族は全てを失う結果にw
A41: 40 | D41: 40 | E41: スカッと成敗ストーリー | F41: https://www.youtube.com/channel/UC1iIGo491nSYyJ_AsgmPzyw | G41: https://www.youtube.com/watch?v=SrlJ46l-aQs | H41: 1 | I41: 2 か月前 | J41: 0 | K41: https://www.youtube.com/watch?v=3v1qqv9z0yE | L41: 35000 | M41: 【スカッとする話】長男が双子の娘を残して他界。長男嫁「発達障害のガキは中卒の貧乏ババァに譲ってあげるw」私「では私が育てます…」10年後、まさかの展開にw
A42: 41 | D42: 41 | E42: 時を越える話 | F42: https://www.youtube.com/channel/UC_n9gc1na-2QpFv6TPInL3w | G42: https://www.youtube.com/watch?v=yVVWvJEjUsg | H42: 1 | I42: 3 週間前 | J42: 1621 | K42: https://www.youtube.com/watch?v=28rOAUunNPw | L42: 58000 | M42: 【スカッとする話】夫から高級化粧品を貰った私。夫「あれ、もう使った？w」私「お義母さんが試してたよ」直後、なぜか夫が慌て出しw【朗読】【スカッと】
A43: 42 | D43: 42 | E43: 涙の向こう側 | F43: https://www.youtube.com/channel/UCOXAYjsxUMpublA1yS1ATIA | G43: https://www.youtube.com/watch?v=SjEoD7MKz0E | H43: 1 | I43: 6 日前 | J43: 2934 | K43: https://www.youtube.com/watch?v=yqCdgYsZcrQ | L43: 47000 | M43: 【スカッとする話】初孫のお食い初めに行くと私を無視する長男夫婦…私「おめでと！」長男・嫁「…」キレた私は家具家電を黙って捨て家を売払い更地にすると…w【朗読】【スカッと】
A44: 43 | D44: 43 | E44: 老いの詩 | F44: https://www.youtube.com/channel/UClKj-HO63gh7qxtT7M0czEQ | G44: https://www.youtube.com/watch?v=SPvJ4YWDGWU | H44: 1 | I44: 1 か月前 | J44: 7 | K44: https://www.youtube.com/watch?v=qNSSnNaMxrs | L44: 80000 | M44: 【スカッとする話】私1人で育てた息子の顔合わせで、なぜか私たちだけお茶漬け…義家族「貧乏人は好きだろ？w」直後、私の存在に気づいた義兄「俺たちの人生終了だ…」【朗読】【スカッと】
A45: 44 | D45: 44 | E45: Ivan Ilencow | F45: https://www.youtube.com/channel/UC6IzQHpKzqIt1DgjPouEefQ | G45: https://www.youtube.com/watch?v=IZLbdwBj7XA | H45: 1 | I45: 2 年前 | J45: 0 | K45: https://www.youtube.com/watch?v=ik5Oxry7o0g | L45: 31000 | M45: 【スカッとする話】勝手に我が家の庭でバーベキューをする長男嫁「お義母さんの家の庭借りてるよw肉とビール無いから買ってきてw」私「え？私の家そこじゃないわよ？」長男嫁「え？」
A46: 45 | D46: 45 | E46: Legacy Apollo | F46: https://www.youtube.com/channel/UC2YwIXq-utTkNLQgcRVloyQ | G46: https://www.youtube.com/watch?v=Vk35R5f7G2w | H46: 1 | I46: 2 年前 | J46: 0 | K46: https://www.youtube.com/watch?v=uSa9TRN9UTA | L46: 44000 | M46: 【スカッとする話】長男夫婦「ババァは口を開くな！」食事さえ許されずガリガリの私…久々に帰国した次男「母さんは食べないの？」私「いつもの事よ…」次男「は？」その後..【修羅場】
A47: 46 | D47: 46 | E47: Pendelton Gideon | F47: https://www.youtube.com/channel/UCIRVjzjmTHwXA3X81dpyNeQ | G47: https://www.youtube.com/watch?v=bK4E6flKw4g | H47: 0.99 | I47: 1 年前 | J47: 1 | K47: https://www.youtube.com/watch?v=8p7Hl5wjPok | L47: 370000 | M47: 【スカッとする話】大雪の中、赤ちゃんを背負い2時間歩いてきた8歳の姪「3000円貸して下さい...」夫「はぁ？貸すわけないだろ！」次の瞬間、ブチギレた夫は...
A48: 47 | D48: 47 | E48: Павел **** | F48: https://www.youtube.com/channel/UCSPg9ALk7YwnsqACClpErGg | G48: https://www.youtube.com/watch?v=EnUXTdRCsLE | H48: 1 | I48: 2 年前 | J48: 2 | K48: https://www.youtube.com/watch?v=UOK61ieeNvk | L48: 26000 | M48: 【スカッとする話】夫と高級寿司屋へ行くと長男と長男嫁の姿が...長男「来年は保険金で生活するぞｗ」長男嫁「フランスでの生活楽しみ～ｗ」→面白い会話が聞こえたので夫と先手を打った結果ｗ
A49: 48 | D49: 48 | E49: 人生スカッと朗読館 | F49: https://www.youtube.com/channel/UChTkZ7g3oCCQG3XSqe69LWQ | G49: https://www.youtube.com/watch?v=R6VSFZgv9rc | H49: 1 | I49: 4 日前 | J49: 0 | K49: https://www.youtube.com/watch?v=eFu4Ak6nNYo | L49: 28000 | M49: 【スカッとする話】結婚式をドタキャンした妹の代わりに、田舎の大工と結婚させられた私。私「バイトして生活費入れるね」夫「必要ないよ！だって…」翌日、半狂乱の妹が自宅に来てw【朗読ドラマ】【スカッと】
A50: 49 | D50: 49 | E50: 夜の語り部5056 | F50: https://www.youtube.com/channel/UCEvaB4r-6y7tj3UAoMEdqXA | G50: https://www.youtube.com/watch?v=-PbKfh2Ga5A | H50: 1 | I50: 1 か月前 | J50: 28 | K50: https://www.youtube.com/watch?v=DPS_qm8jKlI | L50: 100000 | M50: 【スカッとする話】私の年収が1000万と知らず夫と一緒に出ていった息子「毒親とは絶縁wバイバイw」私「じゃあ夫とも縁切るね」息子「勝手にどうぞw」2日後w【朗読】【スカッと】
...

Sheet ラウンド3
A1: No. | B1: 申請日 | C1: 削除確認 | D1: 順位 | E1: チャンネル名 | F1: チャンネルURL | G1: 転載動画URL | H1: 一致率 | I1: 転載の投稿 | J1: 転載の再生数 | K1: 元動画URL | L1: 元動画の再生数 | M1: 元タイトル | N1: メモ
A2: 1 | D2: 1 | E2: 藤田 七海 | F2: https://www.youtube.com/channel/UCe0KTxGVR84qUjkAHQb-wGg | G2: https://www.youtube.com/watch?v=4wCL6JN8awg | H2: 1 | I2: 4 週間前 | J2: 4 | K2: https://www.youtube.com/watch?v=lw1jxku6xxo | L2: 14000 | M2: 【スカッとする話】離婚した3日後に再婚した元夫「金持ちで若い嫁ゲットw」私「ごめん、笑いすぎて腹痛いwだって、その女は…w」真実を知った夫は顔面蒼白にw【朗読】【スカッと】
A3: 2 | D3: 2 | E3: スカッと物語 | F3: https://www.youtube.com/channel/UCLz5UoQMIAja9LyZIOCYmQg | G3: https://www.youtube.com/watch?v=kzk9Ium2XNM | H3: 1 | I3: 7 日前 | J3: 0 | K3: https://www.youtube.com/watch?v=W7iyZQfb2oU | L3: 41000 | M3: 【スカッとする話】父が毎日お茶漬けなので、私「仕送り10万じゃ足りない？」父「仕送り？貰ってないぞ」私「変ね…銀行に電話するわ」直後、夫がガタガタ震え出し…【朗読ドラマ】【朗読】【スカッと】
A4: 3 | D4: 3 | E4: 出る杭は打たれる | F4: https://www.youtube.com/channel/UCAmIDIbiOxKA9YSVK0aYSZQ | G4: https://www.youtube.com/watch?v=cZ_wZEMKHQQ | H4: 1 | I4: 2 か月前 | J4: 0 | K4: https://www.youtube.com/watch?v=7z-EBP9QVbU | L4: 18000 | M4: 【スカッとする話】両親と同居するための新築一軒家が完成すると、夫「お袋の介護か離婚か選べw」私「え？同居するつもり？2週間前から他人なのに？」夫「え？他人？」実はw
A5: 4 | D5: 4 | E5: 良い話 | F5: https://www.youtube.com/channel/UCSrk1OzKlw4sCvRbksLDgcQ | G5: https://www.youtube.com/watch?v=_17PdwgYQtA | H5: 1 | I5: 5 日前 | J5: 0 | K5: https://www.youtube.com/watch?v=VX7Q7VMHXOo | L5: 43000 | M5: 【スカッとする話】新婚3ヶ月で初めて義実家に泊まると、夫「もし嫁イビリされたら教えて」私「大丈夫。全力で反撃するから」結果w【スカッと】【朗読】
A6: 5 | D6: 5 | E6: 家庭の真実 5497 | F6: https://www.youtube.com/channel/UCqzVZHS7_AHD3WczZdnOkwg | G6: https://www.youtube.com/watch?v=Y9etLclFzxg | H6: 1 | I6: 4 週間前 | J6: 22 | K6: https://www.youtube.com/watch?v=6DiHSqB63W0 | L6: 41000 | M6: 【スカッとする話】夫が出張で遠出するたび、私を実家へ帰らせる義母。義母「理由はいいから！」不審に思い静かに家に戻ると、玄関から怪しい声が聞こえ…【朗読】【スカッと】
A7: 6 | D7: 6 | E7: スカッとストーリー 5006 | F7: https://www.youtube.com/channel/UC1x3I0LM2SzXkpn57uaFuQA | G7: https://www.youtube.com/watch?v=Q4TYGcJUdS4 | H7: 1 | I7: 1 か月前 | J7: 16 | K7: https://www.youtube.com/watch?v=p4pyD9SD1Tk | L7: 81000 | M7: 【スカッとする話】義両親に蹴られ骨折した私に夫「寝かせとけば治るw」翌日、病室に嘲笑いに来た義家族「あれ、嫁は？w」医師「警察署です」義家族「え？」【朗読】【スカッと】
A8: 7 | D8: 7 | E8: 嫁ゴコロ逆転朗読館 | F8: https://www.youtube.com/channel/UCQDSjWHn0tvkuVZav4jZnXQ | G8: https://www.youtube.com/watch?v=gf855k-72TE | H8: 1 | I8: 8 日前 | J8: 0 | K8: https://www.youtube.com/watch?v=bUesKx2d9r8 | L8: 27000 | M8: 【スカッとする話】夫「3年間アメリカに赴任する」私「長すぎる！私も一緒に行く」夫「お前は家を守っててくれ」1年後、デパートで夫と妊婦を目撃→証拠を押さえ全て開示すると…w
A9: 8 | D9: 8 | E9: 読書室【スカッとする話】 | F9: https://www.youtube.com/channel/UCjQd7ZVm5BPbGpB_V9B6kgQ | G9: https://www.youtube.com/watch?v=MfZT_x26nhg | H9: 1 | I9: 1 年前 | J9: 0 | K9: https://www.youtube.com/watch?v=Z2pKxDTj5Io | L9: 24000 | M9: 【スカッと】私と息子を捨てて私の妹と再婚した夫「邪魔者2人は失せろw」妹「3日以内に出てってねw」息子「母さん良かったね！」私「え？」息子「だってあの人たち…」
A10: 9 | D10: 9 | E10: 憂鬱よりスカッと | F10: https://www.youtube.com/channel/UC8bvniIkSPPf_5ELr1VNZCQ | G10: https://www.youtube.com/watch?v=mHSslWPvj0E | H10: 1 | I10: 2 年前 | J10: 49 | K10: https://www.youtube.com/watch?v=Ne3lH19M3rA | L10: 95000 | M10: 【スカッとする話】娘「毎月1300円の仕送り助かるよ！毎日半額の弁当食べてるよ！」私「え？毎月13万円振り込んでるわよ？」娘「え？」実は...
A11: 10 | D11: 10 | E11: とする話 | F11: https://www.youtube.com/channel/UC-1KoQRWd1ijwgKpAmRTQ7A | G11: https://www.youtube.com/watch?v=EqQHa2ddtO8 | H11: 1 | I11: 1 年前 | J11: 1 | K11: https://www.youtube.com/watch?v=_1Jc1H2WcQc | L11: 11000 | M11: 【スカッとする話】医者一族と結婚した義妹の結婚式で義妹「中卒の貧乏人は一族の恥wアンタらの席はないから帰れw」夫「帰るか」私「はい」30分後、義妹から鬼電がw
A12: 11 | D12: 11 | E12: Dima Tomashevich | F12: https://www.youtube.com/channel/UCkfiH3lPVPodePE4eNSDpWg | G12: https://www.youtube.com/watch?v=b4Hl6zXY_vI | H12: 1 | I12: 2 年前 | J12: 0 | K12: https://www.youtube.com/watch?v=samZXNv0pmY | L12: 30000 | M12: 【スカッとする話】医者の長男が亡くなり通夜振る舞いで私の席だけない。長男嫁「ババァは帰れw夫の遺産と家は嫁である私が相続しますw」それを聞いた私は大爆笑w→だって長男は…【修羅場】
A13: 12 | D13: 12 | E13: さあ、どうぞ | F13: https://www.youtube.com/channel/UCG-XF2tttCtNESz__p6GQ7w | G13: https://www.youtube.com/watch?v=8i7FiAPnp0Q | H13: 1 | I13: 2 か月前 | J13: 0 | K13: https://www.youtube.com/watch?v=ZOSTbqZ1QDQ | L13: 42000 | M13: 【スカッとする話】私の娘にだけお年玉をくれない義母「アンタに似た低学歴の孫は他人wもらえるのは家族だけよｗ」キレた私は義母への仕送り20万を停止→永久に他人扱いしてやった結果w
... A18: 17 | D18: 17 | E18: 義家族スカッと物語帳 | F18: https://www.youtube.com/channel/UCIZ41RBpQd7wBp_oOTGv1zw | G18: https://www.youtube.com/watch?v=e8AUCDntWUs | H18: 1 | I18: 7 日前 | J18: 1 | K18: https://www.youtube.com/watch?v=qORErX-vqL8 | L18: 32000 | M18: 【スカッとする話】同窓会で東大卒のイケメン医師が中卒でバイトの私に難病症例を提示。医師「解けたら何でもするw」私「あ、それ難しくないよ」【朗読】【スカッと】
A19: 18 | D19: 18 | E19: 静かな夜の物語、雨の中の記憶 | G19: https://www.youtube.com/watch?v=ze9iOqJewBo | H19: 1 | I19: 2 週間前 | J19: 0 | K19: https://www.youtube.com/watch?v=T40Q2m3NnVw | L19: 60000 | M19: 【スカッとする話】私の里帰り中に医者の婚約者を略奪した姉から連絡「彼の赤ちゃん妊娠したwアンタは帰ってくるなw」私「いいの？有り難う！」そのまま新居に引越した結果w
A20: 19 | D20: 19 | E20: Noah Qumi | F20: https://www.youtube.com/channel/UCH4l3-r5NgR2RlKdoRwfzAw | G20: https://www.youtube.com/watch?v=kwDoLkr5Sbk | H20: 1 | I20: 10 日前 | J20: 0 | K20: https://www.youtube.com/watch?v=aCFKEISe330 | L20: 360000 | M20: 【スカッとする話】同窓会で結婚直前に私を捨てた夫と再会。夫「金持ちの社長令嬢と結婚したw俺だけ幸せでごめんなw」私「本当にそう思う？」真実を伝えると元夫が震え出し…【朗読】【スカッと】
A21: 20 | D21: 20 | E21: Shinji Datの人生物語 | F21: https://www.youtube.com/channel/UCpdX_bFCePsYvPWZAMQoaeg | G21: https://www.youtube.com/watch?v=F-JFquYn4l8 | H21: 1 | I21: 2 か月前 | J21: 20 | K21: https://www.youtube.com/watch?v=C6r_ataNQZU | L21: 180000 | M21: 【スカッと総集編】起業した夫を支えてきた私を裏切った夫「21歳のバイトを妊娠させた！悪いが、離婚してくれ！」私「はーい、仕事も辞めるね！」夫「は？仕事は続けてくれよ」
A22: 21 | D22: 21 | E22: スカッとする話 5020 | F22: https://www.youtube.com/channel/UCAG5eZR0aJpGuShtjtimSEg | G22: https://www.youtube.com/watch?v=z0gg-kdn8Io | H22: 1 | I22: 3 週間前 | J22: 39 | K22: https://www.youtube.com/watch?v=azDvOP8I1Ck | L22: 22000 | M22: 【スカッとする話】同窓会に出席した肉屋の私。金持ち同級生「お前肉屋？wじゃあ旦那は豚かw呼べw」1時間後、社長の夫が会場に到着。キレた夫「豚だけど呼んだ？」【朗読】【スカッと】
A23: 22 | D23: 22 | E23: 人生の光と影 | F23: https://www.youtube.com/channel/UCYX4tsWpykTmtfNq_i36C_w | G23: https://www.youtube.com/watch?v=eKijFqrCIO4 | H23: 1 | I23: 5 日前 | J23: 62 | K23: https://www.youtube.com/watch?v=3ROoZpLQQvY | L23: 18000 | M23: 【スカッとする話】姉夫婦の婚約祝いに到着すると息子「ママ、今すぐ帰ろう！早く発車して！」混乱する息子に理由を聞くと、息子「後ろみて…」私「え？」【朗読】【スカッと】
A24: 23 | D24: 23 | E24: 美しい木 | F24: https://www.youtube.com/channel/UCKDhvWl0boDNeo65NQzjbOg | G24: https://www.youtube.com/watch?v=6OMd2U0O26s | H24: 1 | I24: 2 か月前 | J24: 2 | K24: https://www.youtube.com/watch?v=XeaG3k_O8iM | L24: 31000 | M24: 【スカッとする話】夫「もう我慢できん！クズ嫁とは離婚！」夫婦喧嘩の翌日出張から帰ると私「この前はごめ...ん？」机の上に記入済みの離婚届が...速攻で提出してやった結果w
A25: 24 | D25: 24 | E25: TINA SHTIBKO | F25: https://www.youtube.com/channel/UCIQbb4FNm2BhP5GfSTbrQ4w | G25: https://www.youtube.com/watch?v=OJFNQ_YQztc | H25: 1 | I25: 2 年前 | J25: 0 | K25: https://www.youtube.com/watch?v=iknFXLIJR7c | L25: 37000 | M25: 【スカッとする話】兄嫁に奴隷扱いされてる祖母「家から出して！」兄に相談すると「そんならお前らが引き取れ！」私「はい、預かります」祖母を夫の別荘に住ませた結果w
A26: 25 | D26: 25 | E26: フィクション 5634 | F26: https://www.youtube.com/channel/UCtx1aitp-eTJhv2c94bnBZQ | G26: https://www.youtube.com/watch?v=UmOdOkciR2g | H26: 1 | I26: 3 週間前 | J26: 186 | K26: https://www.youtube.com/watch?v=i4CX2w0EpjQ | L26: 65000 | M26: 【スカッとする話】不倫され無一文で追い出された私。偶然見た大富豪の継母募集に応募。1ヶ月後、知らせを聞いた元夫がいきなり家の前に現れ…w【朗読】【スカッと】
A27: 26 | D27: 26 | E27: 泥だらけの絆 5655 | F27: https://www.youtube.com/channel/UCdyvc7k9wPzVO9X62aCvguQ | G27: https://www.youtube.com/watch?v=uVKwqGj4XDE | H27: 1 | I27: 8 日前 | J27: 0 | K27: https://www.youtube.com/watch?v=FKxO2ZIWpyI | L27: 87000 | M27: 【スカッとする話】父「もう限界だ…助けて」息子夫婦から年金と貯金を摂取されボロボロな姿で現れた。私「一緒に暮らそ」父「ええんか？涙」翌日、息子夫婦が泣き叫びw【朗読】【スカッと】
A28: 27 | D28: 27 | E28: Bonnie Denver | F28: https://www.youtube.com/channel/UCsdndA886timZqWK6_b0d0Q | G28: https://www.youtube.com/watch?v=t9IBLjg2a_M | H28: 1 | I28: 1 年前 | J28: 0 | K28: https://www.youtube.com/watch?v=BEKjWcB_3Mk | L28: 56000 | M28: 【スカッと】孫の結婚式に行くと私達夫婦を嫌う新婦「中卒の貧乏ジジババは祝儀置いて田舎に帰れw」夫「…帰るか」私「…うん」30分後、半狂乱の新婦がw
A29: 28 | D29: 28 | E29: 心温まるストーリー 4989 | F29: https://www.youtube.com/channel/UCS-VuYFB_DXsDhPHAzUS0JA | G29: https://www.youtube.com/watch?v=2pKVUEdoXJI | H29: 1 | I29: 3 週間前 | J29: 19 | K29: https://www.youtube.com/watch?v=vQdhdcwgO20 | L29: 21000 | M29: 【スカッとする話】父が急逝し女社長になった私。副社長「これ退職届80人分wコネだけの女は皆無理ってw」翌日、新聞を見た元部下が土下座→全員を無視してあげた結果w【朗読】【スカッと】
A30: 29 | D30: 29 | E30: Jamison Abraham | F30: https://www.youtube.com/channel/UCcUsK23eqHw3ZQA5HjspM9Q | G30: https://www.youtube.com/watch?v=I1fCJmwv5aM | H30: 1 | I30: 1 年前 | J30: 0 | K30: https://www.youtube.com/watch?v=zZV5oL3aIHY | L30: 37000 | M30: 【スカッとする話】孫の七五三祝いに行くと私だけ席がない...夫の連れ子「家族以外は立ってろw」夫「...帰るか」私「うん」直後、連れ子に大惨事がw
